Workbook

Sheet Plan1
A2: Country WB | B2: 1996
A3: WLD | B3: 5.7797144e+09
A4: USA | B4: 269394000
A5: GBR | B5: 58166950
A6: IMN | B6: 72898
A7: AUT | B7: 7959017
A8: BEL | B8: 10156637
A9: DNK | B9: 5263074
A10: FRA | B10: 59752020
A11: DEU | B11: 81914831
A12: SMR | B12: 25914
A13: ITA | B13: 56860281
... A65: JAM | B65: 2509923.4
A66: SXM
A67: CUW
A68: PRI | B68: 3724655
A69: KNA | B69: 43391
A70: LCA | B70: 148962
A71: VCT | B71: 108078
A72: SUR | B72: 441734
A73: TTO | B73: 1258365
A74: VIR | B74: 108093
A75: CYM | B75: 33535
A76: TCA | B76: 15967
A77: BHR | B77: 579697
A78: CYP | B78: 873246
A79: IRN | B79: 61440887
... A216: ROU | B216: 22619004

Sheet Plan2
C1: Labor Force | E1: Desemprego | G1: Emprego
A2: Country WB | B2: Pop | C2: % | D2: Total | E2: % | F2: Total | G2: Total | H2: %
A3: WLD | B3: 5.7797144e+09 | C3: =VLOOKUP(A3,LF!$A$4:$B$251,2,FALSE) -> 65.733946 | D3: =B3*(C3/100) -> 3.7992343e+09 | E3: =VLOOKUP(A3,UN!$A$4:$B$251,2,FALSE) -> 6.1423123 | F3: =D3*(E3/100) -> 2.3336084e+08 | G3: =D3-F3 -> 3.5658735e+09 | H3: =G3/B3 -> 0.61696362
A4: USA | B4: 269394000 | C4: =VLOOKUP(A4,LF!$A$4:$B$251,2,FALSE) -> 65.900002 | D4: =B4*(C4/100) -> 1.7753065e+08 | E4: =VLOOKUP(A4,UN!$A$4:$B$251,2,FALSE) -> 5.5 | F4: =D4*(E4/100) -> 9764185.8 | G4: =D4-F4 -> 1.6776646e+08 | H4: =G4/B4 -> 0.62275501
A5: GBR | B5: 58166950 | C5: =VLOOKUP(A5,LF!$A$4:$B$251,2,FALSE) -> 61.5 | D5: =B5*(C5/100) -> 35772674 | E5: =VLOOKUP(A5,UN!$A$4:$B$251,2,FALSE) -> 8.3000002 | F5: =D5*(E5/100) -> 2969132 | G5: =D5-F5 -> 32803542 | H5: =G5/B5 -> 0.563955
A6: AUT | B6: 7959017 | C6: =VLOOKUP(A6,LF!$A$4:$B$251,2,FALSE) -> 58.299999 | D6: =B6*(C6/100) -> 4640106.9 | E6: =VLOOKUP(A6,UN!$A$4:$B$251,2,FALSE) -> 4.0999999 | F6: =D6*(E6/100) -> 190244.38 | G6: =D6-F6 -> 4449862.5 | H6: =G6/B6 -> 0.55909699
A7: BEL | B7: 10156637 | C7: =VLOOKUP(A7,LF!$A$4:$B$251,2,FALSE) -> 50.400002 | D7: =B7*(C7/100) -> 5118945.2 | E7: =VLOOKUP(A7,UN!$A$4:$B$251,2,FALSE) -> 9.5 | F7: =D7*(E7/100) -> 486299.79 | G7: =D7-F7 -> 4632645.4 | H7: =G7/B7 -> 0.45612001
A8: DNK | B8: 5263074 | C8: =VLOOKUP(A8,LF!$A$4:$B$251,2,FALSE) -> 65.400002 | D8: =B8*(C8/100) -> 3442050.5 | E8: =VLOOKUP(A8,UN!$A$4:$B$251,2,FALSE) -> 6.8000002 | F8: =D8*(E8/100) -> 234059.44 | G8: =D8-F8 -> 3207991 | H8: =G8/B8 -> 0.60952801
A9: FRA | B9: 59752020 | C9: =VLOOKUP(A9,LF!$A$4:$B$251,2,FALSE) -> 55.599998 | D9: =B9*(C9/100) -> 33222122 | E9: =VLOOKUP(A9,UN!$A$4:$B$251,2,FALSE) -> 12.4 | F9: =D9*(E9/100) -> 4119543 | G9: =D9-F9 -> 29102579 | H9: =G9/B9 -> 0.48705599
A10: DEU | B10: 81914831 | C10: =VLOOKUP(A10,LF!$A$4:$B$251,2,FALSE) -> 58.299999 | D10: =B10*(C10/100) -> 47756346 | E10: =VLOOKUP(A10,UN!$A$4:$B$251,2,FALSE) -> 8.8999996 | F10: =D10*(E10/100) -> 4250314.6 | G10: =D10-F10 -> 43506031 | H10: =G10/B10 -> 0.531113
A11: ITA | B11: 56860281 | C11: =VLOOKUP(A11,LF!$A$4:$B$251,2,FALSE) -> 47.200001 | D11: =B11*(C11/100) -> 26838053 | E11: =VLOOKUP(A11,UN!$A$4:$B$251,2,FALSE) -> 11.9 | F11: =D11*(E11/100) -> 3193728.2 | G11: =D11-F11 -> 23644325 | H11: =G11/B11 -> 0.41583201
A12: LUX | B12: 414225 | C12: =VLOOKUP(A12,LF!$A$4:$B$251,2,FALSE) -> 50.900002 | D12: =B12*(C12/100) -> 210840.53 | E12: =VLOOKUP(A12,UN!$A$4:$B$251,2,FALSE) -> 3.3 | F12: =D12*(E12/100) -> 6957.7374 | G12: =D12-F12 -> 203882.79 | H12: =G12/B12 -> 0.49220301
A13: NLD | B13: 15530498 | C13: =VLOOKUP(A13,LF!$A$4:$B$251,2,FALSE) -> 59.099998 | D13: =B13*(C13/100) -> 9178524.1 | E13: =VLOOKUP(A13,UN!$A$4:$B$251,2,FALSE) -> 6.4000001 | F13: =D13*(E13/100) -> 587425.55 | G13: =D13-F13 -> 8591098.5 | H13: =G13/B13 -> 0.55317599
A14: SWE | B14: 8840998 | C14: =VLOOKUP(A14,LF!$A$4:$B$251,2,FALSE) -> 63.099998 | D14: =B14*(C14/100) -> 5578669.6 | E14: =VLOOKUP(A14,UN!$A$4:$B$251,2,FALSE) -> 10.1 | F14: =D14*(E14/100) -> 563445.65 | G14: =D14-F14 -> 5015224 | H14: =G14/B14 -> 0.56726898
... A41: ROU | B41: 22619004 | C41: =VLOOKUP(A41,LF!$A$4:$B$251,2,FALSE) -> 64.5 | D41: =B41*(C41/100) -> 14589258 | E41: =VLOOKUP(A41,UN!$A$4:$B$251,2,FALSE) -> 6.6999998 | F41: =D41*(E41/100) -> 977480.23 | G41: =D41-F41 -> 13611777 | H41: =G41/B41 -> 0.601785
A42: TWN | B42: 20000000 | D42: =B42*(C42/100) -> 0 | F42: =D42*(E42/100) -> 0 | G42: =D42-F42 -> 0 | H42: =G42/B42 -> 0
A44: 40 | B44: =SUM(B4:B42) -> 2872267109 | D44: =SUM(D4:D42) -> 1.9624877e+09 | F44: =SUM(F4:F42) -> 1.1567694e+08 | G44: =SUM(G4:G42) -> 1.8468108e+09 | H44: =G44/B44 -> 0.64298016
A45: ROW | B45: =B3-B44 -> 2.9074473e+09 | D45: =D3-D44 -> 1.8367466e+09 | F45: =F3-F44 -> 1.176839e+08 | G45: =G3-G44 -> 1.7190627e+09 | H45: =G45/B45 -> 0.59126188
A47: PE-ROW | B47: 1.1937945e+09
B48: =B47/B45 -> 0.41059883
A50: PE-40 | B50: =A58 -> 1.8294535e+09
B51: =B50/B44 -> 0.6369371
A52: Ao estimar o emprego mundial pela situação da nação com o pior desempenho, subestimamos a participação do resto do mundo no processo produtivo. Com efeito, temos uma estimativa mais conservadora. --- Observe que a população ocupada no mundo resto do mundo é de 1.7 bilhões. Nossa estimativa aponta para 1.2 bilhões, o que é 500 milhões menos do que o real.
A57: 421880 | B57: 86150 | C57: 176500 | D57: 89550 | E57: 15500 | F57: 44625 | G57: 139925 | H57: 7750 | I57: 57025 | J57: 42575 | K57: 47625 | L57: 186600 | M57: 82700 | N57: 60825 | O57: 104250 | P57: 73725 | Q57: 66450 | R57: 585670 | S57: 289900 | T57: 451780 | U57: 986870 | V57: 397950 | W57: 246625 | X57: 11625 | Y57: 48875 | Z57: 89675 | AA57: 163950 | AB57: 317825 | AC57: 93000 | AD57: 736235 | AE57: 367600 | AF57: 582020 | AG57: 771000 | AH57: 510295 | AI57: 0 | AJ57: 336960 | AK57: 8453 | AL57: 89592 | AM57: 40239 | AN57: 7753 | AO57: 39536 | AP57: 54281 | AQ57: 2862 | AR57: 28258 | AS57: 28113 | AT57: 37836 | AU57: 101661 | AV57: 78160 | AW57: 81664 | AX57: 30598 | AY57: 56729 | AZ57: 34465 | BA57: 292916 | BB57: 82345 | BC57: 191922 | BD57: 294351 | BE57: 202681 | BF57: 144993 | BG57: 476 | BH57: 6823 | BI57: 32479 | BJ57: 63958 | BK57: 120854 | BL57: 49926 | BM57: 227927 | BN57: 259146 | BO57: 221765 | BP57: 299263 | BQ57: 188950 | BR57: 7672 | BS57: 93298 | BT57: 4137 | BU57: 99996 | BV57: 62232 | BW57: 3819 | BX57: 13986 | BY57: 51927 | BZ57: 6055 | CA57: 70147 | CB57: 23822 | CC57: 35603 | CD57: 108972 | CE57: 43402 | CF57: 56388 | CG57: 62934 | CH57: 34152 | CI57: 28148 | CJ57: 235059 | CK57: 73323 | CL57: 202290 | CM57: 295169 | CN57: 146022 | CO57: 115121 | CP57: 7044 | CQ57: 12566 | CR57: 61813 | CS57: 81723 | CT57: 143835 | CU57: 19774 | CV57: 446622 | CW57: 369880 | CX57: 314771 | CY57: 354222 | CZ57: 140571 | DA57: 58779 | DB57: 825600 | DC57: 49243.955 | DD57: 148836.92 | DE57: 191812.67 | DF57: 26829.494 | DG57: 25008.487 | DH57: 33263.716 | DI57: 12747.045 | DJ57: 41761.746 | DK57: 22094.877 | DL57: 32535.314 | DM57: 74539.861 | DN57: 98091.543 | DO57: 43825.553 | DP57: 16510.458 | DQ57: 33263.716 | DR57: 73805.138 | DS57: 162800 | DT57: 35474.673 | DU57: 285721.72 | DV57: 69015.942 | DW57: 103982.08 | DX57: 69118.038 | DY57: 34317.752 | DZ57: 21241.562 | EA57: 42285.803 | EB57: 49640.777 | EC57: 32472.715 | ED57: 87397.883 | EE57: 17118.124 | EF57: 300551.02 | EG57: 264058.13 | EH57: 180767.07 | EI57: 108023.78 | EJ57: 0 | EK57: 17709273 | EL57: 232345.4 | EM57: 1593077.4 | EN57: 2361588.9 | EO57: 446251.25 | EP57: 434754.35 | EQ57: 554162.03 | ER57: 76628.229 | ES57: 467928.46 | ET57: 272945.04 | EU57: 471579.1 | EV57: 732530.19 | EW57: 371486.89 | EX57: 346932.05 | EY57: 330928.1 | EZ57: 743343.21 | FA57: 328212.4 | FB57: 4527756.6 | FC57: 1511844.2 | FD57: 1581271 | FE57: 7689739.9 | FF57: 2706595.3 | FG57: 2018458.3 | FH57: 33314.397 | FI57: 73132.531 | FJ57: 516919.2 | FK57: 263728.03 | FL57: 849643.17 | FM57: 580651.95 | FN57: 4936498 | FO57: 3377812.7 | FP57: 3512739.7 | FQ57: 2123369.3 | FR57: 8208205.2 | FS57: 0 | FT57: 531097.96 | FU57: 148874.76 | FV57: 262048.46 | FW57: 136960.51 | FX57: 12536.973 | FY57: 134530.08 | FZ57: 273829.39 | GA57: 13187.336 | GB57: 99879.682 | GC57: 96410.818 | GD57: 51061.911 | GE57: 238671.59 | GF57: 137548.65 | GG57: 121132.34 | GH57: 225038.3 | GI57: 130340.2 | GJ57: 95989.351 | GK57: 860410 | GL57: 117977.69 | GM57: 723203.47 | GN57: 1661197 | GO57: 912416.37 | GP57: 331726.47 | GQ57: 20097.849 | GR57: 80671.309 | GS57: 108102.91 | GT57: 251155.23 | GU57: 623426.85 | GV57: 79343.247 | GW57: 792492.43 | GX57: 1061180.9 | GY57: 885666 | GZ57: 1120087.7 | HA57: 1192632.1 | HB57: 208296.43 | HC57: 348200000 | HD57: 12848811 | HE57: 10948555 | HF57: 15538965 | HG57: 2624103.4 | HH57: 3692936.3 | HI57: 4849211.6 | HJ57: 925276.87 | HK57: 7632792.4 | HL57: 5182087.4 | HM57: 14269093 | HN57: 10358801 | HO57: 10040754 | HP57: 7050089.8 | HQ57: 4775987.7 | HR57: 10140994 | HS57: 2815627.9 | HT57: 38335913 | HV57: 11206398 | HW57: 30143328 | HX57: 11330865 | HY57: 14225150 | HZ57: 1870200.2 | IA57: 587869.49 | IB57: 2202895.6 | IC57: 4622204.6 | ID57: 3321527 | IE57: 955507.78 | IF57: 3549028.9 | IG57: 12432976 | IH57: 17210515 | II57: 5209792.4 | IJ57: 60401742 | IL57: 21200 | IM57: 700 | IN57: 9790.8176 | IO57: 9254.8936 | IP57: 1547.6869 | IQ57: 2774.4145 | IR57: 2894.6933 | IS57: 130.30639 | IT57: 1141.2186 | IU57: 1683.5581 | IV57: 2794.6946 | IW57: 3405.2033 | IX57: 1382.8257 | IY57: 703.94217 | IZ57: 569.56562 | JA57: 4426.1796 | JB57: 1400 | JC57: 27500 | JD57: 8566.2684 | JE57: 14940.554 | JF57: 29193.178 | JG57: 31700 | JH57: 5826.4126 | JI57: 1875.4642 | JJ57: 2724.8337 | JK57: 6543.1688 | JL57: 2230.1207 | JM57: 13300 | JN57: 2110.074 | JO57: 11689.926 | JP57: 27000 | JQ57: 15600 | JR57: 11100 | JS57: 15000 | JT57: 5000 | JU57: 318142 | JV57: 94669 | JW57: 172299 | JX57: 153777 | JY57: 32204 | JZ57: 72627 | KA57: 64961 | KB57: 12205 | KC57: 46792 | KD57: 45296 | KE57: 90604 | KF57: 264135 | KG57: 183444 | KH57: 142718 | KI57: 94292 | KJ57: 83074 | KK57: 82066 | KL57: 507652 | KM57: 75775 | KN57: 260138 | KO57: 413284 | KP57: 153950 | KQ57: 232767 | KR57: 3639 | KS57: 5413 | KT57: 36094 | KU57: 78322 | KV57: 86149 | KW57: 59626 | KX57: 335004 | KY57: 289204 | KZ57: 271124 | LA57: 268128 | LB57: 164841 | LC57: 749 | LD57: 971000 | LE57: 179000 | LF57: 905000 | LG57: 306000 | LH57: 40000 | LI57: 237000 | LJ57: 759000 | LK57: 23000 | LL57: 551000 | LM57: 397000 | LN57: 334000 | LO57: 1171000 | LP57: 1127000 | LQ57: 1105000 | LR57: 889000 | LS57: 372000 | LT57: 356000 | LU57: 3135000 | LV57: 788000 | LW57: 1719000 | LX57: 3294000 | LY57: 1386000 | LZ57: 1000000 | MA57: 26000 | MB57: 46000 | MC57: 446000 | MD57: 595000 | ME57: 1244000 | MF57: 346000 | MG57: 3020000 | MH57: 3014000 | MI57: 2041000 | MJ57: 3345000 | MK57: 1746000 | ML57: 585000 | MM57: 108343 | MN57: 3486 | MO57: 85487 | MP57: 17853 | MQ57: 1481 | MR57: 15253 | MS57: 52642 | MT57: 807 | MU57: 25891 | MV57: 20516 | MW57: 19592 | MX57: 56611 | MY57: 71007 | MZ57: 44152 | NA57: 21775 | NB57: 32312 | NC57: 16897 | ND57: 147803 | NE57: 61921 | NF57: 163704 | NG57: 184497 | NH57: 75773 | NI57: 72194 | NJ57: 18578 | NK57: 7811 | NL57: 28476 | NM57: 46773 | NN57: 78887 | NO57: 31731 | NP57: 182494 | NQ57: 168065 | NR57: 182882 | NS57: 412933 | NT57: 113778 | NU57: 11711 | NV57: 1072588 | NW57: 48020 | NX57: 400507 | NY57: 239102 | NZ57: 82418 | OA57: 92566 | OB57: 179770 | OC57: 8246 | OD57: 137334 | OE57: 93886 | OF57: 158830 | OG57: 342668 | OH57: 157189 | OI57: 166295 | OJ57: 242536 | OK57: 198208 | OL57: 78159 | OM57: 1337385 | ON57: 289607 | OO57: 481078 | OP57: 1347471 | OQ57: 817158 | OR57: 450959 | OS57: 11452 | OT57: 28261 | OU57: 109274 | OV57: 189805 | OW57: 348630 | OX57: 76119 | OY57: 859543 | OZ57: 1129023 | PA57: 741946 | PB57: 760467 | PC57: 1119499 | PD57: 0 | PE57: 60200 | PF57: 8800 | PG57: 28900 | PH57: 26600 | PI57: 3100 | PJ57: 17300 | PK57: 5900 | PL57: 3337.3012 | PM57: 4862.6988 | PN57: 2200 | PO57: 7200 | PP57: 5800 | PQ57: 9300 | PR57: 7700 | PS57: 7800 | PT57: 18400 | PU57: 15700 | PV57: 35500 | PW57: 13600 | PX57: 21000 | PY57: 47900 | PZ57: 17000 | QA57: 26598.119 | QB57: 5005.2734 | QC57: 1479.9212 | QD57: 17116.686 | QE57: 11700 | QF57: 6300 | QG57: 8388.2353 | QH57: 22611.765 | QI57: 33700 | QJ57: 54100 | QK57: 35000 | QL57: 29200 | QM57: 0 | QN57: 152100 | QO57: 5500 | QP57: 45500 | QQ57: 17000 | QR57: 3500 | QS57: 28600 | QT57: 71500 | QU57: 3400 | QV57: 18600 | QW57: 14200 | QX57: 13500 | QY57: 48000 | QZ57: 58900 | RA57: 53900 | RB57: 23600 | RC57: 16500 | RD57: 19900 | RE57: 123200 | RF57: 41500 | RG57: 85700 | RH57: 128500 | RI57: 62000 | RJ57: 73500 | RK57: 10800 | RL57: 5400 | RM57: 25100 | RN57: 45100 | RO57: 44700 | RP57: 30800 | RQ57: 128700 | RR57: 156800 | RS57: 139400 | RT57: 288500 | RU57: 92700 | RV57: 5200 | RW57: 1026500 | RX57: 49200 | RY57: 545700 | RZ57: 267900 | SA57: 51200 | SB57: 97200 | SC57: 309300 | SD57: 33200 | SE57: 154800 | SF57: 192900 | SG57: 152600 | SH57: 581900 | SI57: 345500 | SJ57: 422600 | SK57: 332900 | SL57: 190400 | SM57: 171600 | SN57: 1426200 | SO57: 452400 | SP57: 891600 | SQ57: 1645800 | SR57: 783200 | SS57: 589200 | ST57: 19400 | SU57: 69912.378 | SV57: 280787.62 | SW57: 436400 | SX57: 730100 | SY57: 250100 | SZ57: 2490900 | TA57: 2289000 | TB57: 1831500 | TC57: 2552300 | TD57: 851000 | TE57: 264500 | TF57: 581000 | TG57: 87495.599 | TH57: 563857.55 | TI57: 240939.83 | TJ57: 29221.309 | TK57: 62892.565 | TL57: 532757.38 | TM57: 79555.139 | TN57: 403708.95 | TO57: 206329.14 | TP57: 159357.5 | TQ57: 561929.24 | TR57: 389073.58 | TS57: 545019.45 | TT57: 514562.04 | TU57: 164796.32 | TV57: 155189.39 | TW57: 1792000 | TX57: 641746.72 | TY57: 1539781.6 | TZ57: 1843995.8 | UA57: 1012929.8 | UB57: 902828.62 | UC57: 100867.44 | UD57: 260151.33 | UE57: 676283.27 | UF57: 1049415.5 | UG57: 1556513.5 | UH57: 1389485.1 | UI57: 1878001.4 | UJ57: 2322338.7 | UK57: 2348925.1 | UL57: 2411759.6 | UM57: 962524.83 | UN57: 196451.82 | UO57: 783819 | UP57: 15467 | UQ57: 107267 | UR57: 109176 | US57: 10455 | UT57: 26274 | UU57: 39168 | UV57: 4472 | UW57: 23876 | UX57: 14808 | UY57: 32418 | UZ57: 42708 | VA57: 24107 | VB57: 14078 | VC57: 22638 | VD57: 42078 | VE57: 36176 | VF57: 271201 | VG57: 98515 | VH57: 210526 | VI57: 430497 | VJ57: 242411 | VK57: 173372 | VL57: 20646 | VM57: 17923 | VN57: 36164 | VO57: 38704 | VP57: 88340 | VQ57: 2249 | VR57: 158632 | VS57: 361950 | VT57: 232588 | VU57: 166951 | VV57: 157916 | VW57: 57284 | VX57: 622659 | VY57: 32815 | VZ57: 174534 | WA57: 128709 | WB57: 35096 | WC57: 37233 | WD57: 47445 | WE57: 5924 | WF57: 64235 | WG57: 29264 | WH57: 33165 | WI57: 88980 | WJ57: 79875 | WK57: 102838 | WL57: 40600 | WM57: 30528 | WN57: 88934 | WO57: 215868 | WP57: 54189 | WQ57: 61911 | WR57: 377395 | WS57: 115159 | WT57: 218303 | WU57: 4363 | WV57: 8107 | WW57: 16844 | WX57: 77411 | WY57: 82665 | WZ57: 20004 | XA57: 123819 | XB57: 284856 | XC57: 326030 | XD57: 233497 | XE57: 166844 | XF57: 0 | XG57: 39834357 | XH57: 863314.37 | XI57: 3535980.3 | XJ57: 1563914.1 | XK57: 543623.77 | XL57: 2128748.5 | XM57: 236160.18 | XN57: 31377.285 | XO57: 221609.26 | XP57: 843695.59 | XQ57: 797145.86 | XR57: 346608.22 | XS57: 108181.29 | XT57: 123563.18 | XU57: 465105.36 | XV57: 518027.73 | XW57: 180974.98 | XX57: 4012367.3 | XZ57: 8703157.1 | YA57: 5212091.4 | YB57: 963093.17 | YC57: 3095074.8 | YD57: 425019.37 | YE57: 46174.475 | YF57: 353036.72 | YG57: 136378.77 | YH57: 500076.46 | YI57: 59507.059 | YJ57: 320579.82 | YK57: 3375915.2 | YL57: 4840372.9 | YM57: 879542.35 | YN57: 3645478.3 | YO57: 0 | YP57: 2.4460972e+08 | YQ57: 2574472.6 | YR57: 10507675 | YS57: 9845959.3 | YT57: 517333.5 | YU57: 4211552.5 | YV57: 1213702.1 | YW57: 194579.04 | YX57: 1923354.7 | YY57: 887914.3 | YZ57: 3562452.1 | ZA57: 3374708.3 | ZB57: 1557689.8 | ZC57: 1189855.6 | ZD57: 665848.88 | ZE57: 3501847 | ZF57: 1220057.1 | ZG57: 15007451 | ZH57: 1699818.4 | ZI57: 3501985.2 | ZJ57: 26282339 | ZK57: 3814338 | ZL57: 10949024 | ZM57: 225483.13 | ZN57: 77389.156 | ZO57: 463611.21 | ZP57: 1038565.7 | ZQ57: 2394138.6 | ZR57: 191199.27 | ZS57: 1940922.6 | ZT57: 10283337 | ZU57: 7409294.4 | ZV57: 2434318.3 | ZW57: 12151589 | ZX57: 2077309.7 | ZY57: 139481 | ZZ57: 4988 | AAA57: 50750 | AAB57: 20775 | AAC57: 1201 | AAD57: 5575 | AAE57: 23564 | AAF57: 7855.3532 | AAG57: 20815 | AAH57: 11473 | AAI57: 11486 | AAJ57: 17466 | AAK57: 16384 | AAL57: 51554 | AAM57: 10313 | AAN57: 6012.6468 | AAO57: 13875 | AAP57: 101137 | AAQ57: 26200 | AAR57: 43138 | AAS57: 116768 | AAT57: 74226 | AAU57: 13825.54 | AAV57: 3276.548 | AAW57: 10728.165 | AAX57: 12121.747 | AAY57: 22148 | AAZ57: 50522 | ABA57: 5478 | ABB57: 74587 | ABC57: 72973 | ABD57: 96181 | ABE57: 115220 | ABF57: 68472 | ABG57: 10593 | ABH57: 1251500 | ABI57: 41600 | ABJ57: 466800 | ABK57: 740700 | ABL57: 237400 | ABM57: 186800 | ABN57: 282400 | ABO57: 25700 | ABP57: 210000 | ABQ57: 198900 | ABR57: 261400 | ABS57: 788600 | ABT57: 540000 | ABU57: 440300 | ABV57: 298200 | ABW57: 327600 | ABX57: 163500 | ABY57: 1469300 | ABZ57: 535300 | ACA57: 923800 | ACB57: 1889700 | ACC57: 878300 | ACD57: 544200 | ACE57: 24800 | ACF57: 23000 | ACG57: 245500 | ACH57: 281500 | ACI57: 592800 | ACJ57: 81700 | ACK57: 1700200 | ACL57: 1484000 | ACM57: 1561700 | ACN57: 1314500 | ACO57: 866900 | ACP57: 1087400 | ACQ57: 4576648.1 | ACR57: 92967.663 | ACS57: 1562201.6 | ACT57: 1226399 | ACU57: 95678.849 | ACV57: 578160.6 | ACW57: 1048480.3 | ACX57: 26385.709 | ACY57: 502108.09 | ACZ57: 753158.5 | ADA57: 512828.13 | ADB57: 2187815.1 | ADC57: 1313064.6 | ADD57: 2126044.7 | ADE57: 1172516.2 | ADF57: 377329.79 | ADG57: 444063.08 | ADH57: 6915393 | ADI57: 461541.29 | ADJ57: 4497984.1 | ADK57: 6622159.5 | ADL57: 4548809.7 | ADM57: 2727819.5 | ADN57: 202108.56 | ADO57: 56505.263 | ADP57: 442642.51 | ADQ57: 580215.19 | ADR57: 2052000 | ADS57: 977257.73 | ADT57: 4752347.7 | ADU57: 3017265.9 | ADV57: 1990807.5 | ADW57: 4181858.4 | ADX57: 4284159.9 | ADY57: 0 | ADZ57: 2323000 | AEA57: 23000 | AEB57: 302080.17 | AEC57: 682258.47 | AED57: 98772.728 | AEE57: 44493.305 | AEF57: 260473.42 | AEG57: 46371.68 | AEH57: 284160.87 | AEI57: 240136.01 | AEJ57: 219031.56 | AEK57: 485002.04 | AEL57: 499851.66 | AEM57: 861649.02 | AEN57: 557832.84 | AEO57: 142886.22 | AEP57: 75000 | AEQ57: 1983000 | AER57: 222528.76 | AES57: 1589695.3 | AET57: 2095775.9 | AEU57: 1782000 | AEV57: 489389.92 | AEW57: 242665.26 | AEX57: 113601.25 | AEY57: 144752.85 | AEZ57: 128590.72 | AFA57: 758000 | AFB57: 264834.54 | AFC57: 763165.46 | AFD57: 644000 | AFE57: 1073000 | AFF57: 311000 | AFG57: 1085000 | AFI57: 300100 | AFJ57: 3500 | AFK57: 62400 | AFL57: 57000 | AFM57: 7400 | AFN57: 20000 | AFO57: 12300 | AFP57: 3800 | AFQ57: 10000 | AFR57: 4500 | AFS57: 17800 | AFT57: 9000 | AFU57: 24100 | AFV57: 25800 | AFW57: 9900 | AFX57: 13600 | AFY57: 42300 | AFZ57: 98500 | AGA57: 41700 | AGB57: 38100 | AGC57: 131100 | AGD57: 17500 | AGE57: 55800 | AGF57: 4800 | AGG57: 1600 | AGH57: 9500 | AGI57: 23200 | AGJ57: 17000 | AGK57: 10500 | AGL57: 41200 | AGM57: 78000 | AGN57: 147000 | AGO57: 102900 | AGP57: 51600 | AGQ57: 0 | AGR57: 4500 | AGS57: 300 | AGT57: 4200 | AGU57: 1000 | AGV57: 0 | AGW57: 400 | AGX57: 2100 | AGY57: 0 | AGZ57: 1300 | AHA57: 3800 | AHB57: 2900 | AHC57: 11500 | AHD57: 2600 | AHE57: 1900 | AHF57: 300 | AHG57: 700 | AHH57: 1500 | AHI57: 24500 | AHJ57: 5600 | AHK57: 12200 | AHL57: 16700 | AHM57: 11800 | AHN57: 8626.6968 | AHO57: 70.135747 | AHP57: 2244.3439 | AHQ57: 1753.3937 | AHR57: 2805.4299 | AHS57: 22500 | AHT57: 2100 | AHU57: 22000 | AHV57: 11900 | AHW57: 10400 | AHX57: 14100 | AHY57: 8200 | AHZ57: 4800 | AIA57: 163400 | AIB57: 2500 | AIC57: 43018.477 | AID57: 29097.378 | AIE57: 1483.3958 | AIF57: 37883.645 | AIG57: 11524.844 | AIH57: 78.318179 | AII57: 3993.7578 | AIJ57: 2510.362 | AIK57: 6732.3346 | AIL57: 12095.381 | AIM57: 9128.5893 | AIN57: 6390.0125 | AIO57: 7074.6567 | AIP57: 11524.844 | AIQ57: 17800 | AIR57: 50700 | AIS57: 11051.064 | AIT57: 30822.695 | AIU57: 74726.241 | AIV57: 15900 | AIW57: 49049.148 | AIX57: 543.24097 | AIY57: 448.76428 | AIZ57: 20170.773 | AJA57: 13888.073 | AJB57: 14200 | AJC57: 17278.073 | AJD57: 22355.98 | AJE57: 60600 | AJF57: 94700 | AJG57: 57700 | AJH57: 50000 | AJI57: 900 | AJJ57: 6859169.3 | AJK57: 177519.25 | AJL57: 1260321.7 | AJM57: 875199.29 | AJN57: 169032.98 | AJO57: 97016.557 | AJP57: 325386.84 | AJQ57: 85646.461 | AJR57: 301156.55 | AJS57: 309636.02 | AJT57: 280041.71 | AJU57: 405715.08 | AJV57: 259849.14 | AJW57: 819943.49 | AJX57: 674211.2 | AJY57: 383899.22 | AJZ57: 183196.24 | AKA57: 2529585.2 | AKB57: 675724.89 | AKC57: 959379.84 | AKD57: 3152745 | AKE57: 2205463.5 | AKF57: 1186595.3 | AKG57: 44442.29 | AKH57: 69799.726 | AKI57: 269390.81 | AKJ57: 116589.52 | AKK57: 251079.91 | AKL57: 111362.03 | AKM57: 922512.41 | AKN57: 1620930.7 | AKO57: 2724327.2 | AKP57: 811187.26 | AKQ57: 753328.55 | AKR57: 2435133.3 | AKS57: 3258.7901 | AKT57: 327.68736 | AKU57: 3967.027 | AKV57: 2680.8143 | AKW57: 375.74755 | AKX57: 86.710974 | AKY57: 1820.9304 | AKZ57: 14.451829 | ALA57: 614.20273 | ALB57: 1875.1248 | ALC57: 679.23596 | ALD57: 755.10806 | ALE57: 458.84557 | ALF57: 10777.451 | ALG57: 1387.3756 | ALH57: 3013.2063 | ALI57: 2345.9436 | ALJ57: 10063.911 | ALK57: 2645.1647 | ALL57: 8427.3087 | ALM57: 7324.0491 | ALN57: 9814.7667 | ALO57: 2662.1902 | ALP57: 582.12237 | ALQ57: 1505.361 | ALR57: 5283.5948 | ALS57: 5461.5685 | ALT57: 4215.4894 | ALU57: 4643.0788 | ALV57: 4273.9897 | ALW57: 12369.282 | ALX57: 9638.8146 | ALY57: 8525.4201 | ALZ57: 7305.9882 | AMA57: 307.50894 | AMB57: 286718 | AMC57: 10883 | AMD57: 155202 | AME57: 31281 | AMF57: 4600 | AMG57: 22763 | AMH57: 140838 | AMI57: 7147 | AMJ57: 74395 | AMK57: 31334 | AML57: 34849 | AMM57: 128916 | AMN57: 84002 | AMO57: 103156 | AMP57: 53997 | AMQ57: 140026 | AMR57: 36459 | AMS57: 433234 | AMT57: 134987 | AMU57: 439661 | AMV57: 642264 | AMW57: 263122 | AMX57: 185621 | AMY57: 24438 | AMZ57: 28705 | ANA57: 75264 | ANB57: 101709 | ANC57: 239558 | AND57: 64585 | ANE57: 1055673 | ANF57: 467138 | ANG57: 372137 | ANH57: 836375 | ANI57: 322714 | ANJ57: 281068 | ANK57: 4021300 | ANL57: 357200 | ANM57: 521107 | ANN57: 499495.01 | ANO57: 98853.52 | ANP57: 142050.34 | ANQ57: 122888.59 | ANR57: 14044.418 | ANS57: 136016.87 | ANT57: 117873.76 | ANU57: 154555.83 | ANV57: 384083.82 | ANW57: 282449.86 | ANX57: 188858.88 | ANY57: 219695.73 | ANZ57: 213526.37 | AOA57: 277600 | AOB57: 842900 | AOC57: 256213.18 | AOD57: 744304.66 | AOE57: 900282.16 | AOF57: 198100 | AOG57: 415402.88 | AOH57: 35436.216 | AOI57: 23466.416 | AOJ57: 200156.78 | AOK57: 180037.71 | AOL57: 271200 | AOM57: 371442.46 | AON57: 217757.54 | AOO57: 402100 | AOP57: 857000 | AOQ57: 1018000 | AOR57: 306036.57 | AOS57: 29163.429 | AOT57: 665300 | AOU57: 14800 | AOV57: 121300 | AOW57: 289300 | AOX57: 77400 | AOY57: 63400 | AOZ57: 55900 | APA57: 1400 | APB57: 25000 | APC57: 23300 | APD57: 72100 | APE57: 91900 | APF57: 45200 | APG57: 56400 | APH57: 36900 | API57: 66500 | APJ57: 29900 | APK57: 429100 | APL57: 90921.823 | APM57: 315423.35 | APN57: 304454.83 | APO57: 216500 | APP57: 94492.724 | APQ57: 1759.9622 | APR57: 10865.791 | APS57: 29683.693 | APT57: 28897.83 | APU57: 95900 | APV57: 14385.739 | APW57: 202414.26 | APX57: 303100 | APY57: 256200 | APZ57: 220600 | AQA57: 116600 | AQB57: 139700 | AQC57: 3326400 | AQD57: 250300 | AQE57: 259309.49 | AQF57: 507068.94 | AQG57: 92060.529 | AQH57: 227377.05 | AQI57: 55145.729 | AQJ57: 68620.764 | AQK57: 79717.851 | AQL57: 37594.214 | AQM57: 112329.7 | AQN57: 277766.89 | AQO57: 314228.74 | AQP57: 98967.9 | AQQ57: 153773.92 | AQR57: 17438.28 | AQS57: 189100 | AQT57: 474400 | AQU57: 80294.007 | AQV57: 312488.48 | AQW57: 378917.51 | AQX57: 115600 | AQY57: 397084.95 | AQZ57: 7115.7996 | ARA57: 12715.117 | ARB57: 6065.9275 | ARC57: 124001.56 | ARD57: 71300 | ARE57: 24771.378 | ARF57: 232728.62 | ARG57: 125100 | ARH57: 441300 | ARI57: 337200 | ARJ57: 170600 | ARK57: 0 | ARL57: 20277389 | ARM57: 981204.64 | ARN57: 1544693.2 | ARO57: 1011138 | ARP57: 152011.86 | ARQ57: 469947.54 | ARR57: 347728.41 | ARS57: 236254.42 | ART57: 610341.78 | ARU57: 210023.83 | ARV57: 828524.45 | ARW57: 1177299.5 | ARX57: 2280063.4 | ARY57: 1090563.7 | ARZ57: 1301253 | ASA57: 373402.21 | ASB57: 1486091.5 | ASC57: 5156061.4 | ASD57: 739443.1 | ASE57: 3217273.5 | ASF57: 2617796.5 | ASG57: 686009.38 | ASH57: 3247291.1 | ASI57: 201572.16 | ASJ57: 156203.72 | ASK57: 543732.84 | ASL57: 828509.26 | ASM57: 600692.87 | ASN57: 1306618.7 | ASO57: 3134328.7 | ASP57: 2908609.4 | ASQ57: 6533849.3 | ASR57: 4607593.5 | ASS57: 2088807.6 | AST57: 0 | ASU57: 172380 | ASV57: 20547 | ASW57: 66405 | ASX57: 69254 | ASY57: 25523 | ASZ57: 28889 | ATA57: 32176 | ATB57: 6273 | ATC57: 28024 | ATD57: 18856 | ATE57: 31824 | ATF57: 87013 | ATG57: 82358 | ATH57: 56749 | ATI57: 26836 | ATJ57: 26839 | ATK57: 41302 | ATL57: 157442 | ATM57: 17421 | ATN57: 128811 | ATO57: 124500 | ATP57: 59842 | ATQ57: 109137 | ATR57: 1721 | ATS57: 405 | ATT57: 14108 | ATU57: 35517 | ATV57: 31806 | ATW57: 19098 | ATX57: 107492 | ATY57: 140247 | ATZ57: 175551 | AUA57: 129819 | AUB57: 76949 | AUC57: 0 | AUD57: 121728 | AUE57: 7578 | AUF57: 21910 | AUG57: 39184 | AUH57: 10636 | AUI57: 15576 | AUJ57: 18634 | AUK57: 854 | AUL57: 14558 | AUM57: 12239 | AUN57: 12012 | AUO57: 39623 | AUP57: 24799 | AUQ57: 29343 | AUR57: 11496 | AUS57: 18255 | AUT57: 13353 | AUU57: 57644 | AUV57: 15405 | AUW57: 45776 | AUX57: 55186 | AUY57: 27165 | AUZ57: 31451 | AVA57: 994 | AVB57: 756 | AVC57: 9636 | AVD57: 8879 | AVE57: 17334 | AVF57: 1484 | AVG57: 57588 | AVH57: 36964 | AVI57: 49842 | AVJ57: 43992 | AVK57: 26322 | AVL57: 1318 | AVM57: 140900 | AVN57: 8500 | AVO57: 68200 | AVP57: 14300 | AVQ57: 1700 | AVR57: 39400 | AVS57: 107000 | AVT57: 3000 | AVU57: 38700 | AVV57: 27200 | AVW57: 20100 | AVX57: 110000 | AVY57: 103100 | AVZ57: 100700 | AWA57: 92800 | AWB57: 55800 | AWC57: 29900 | AWD57: 205100 | AWE57: 70395.834 | AWF57: 241962.82 | AWG57: 189441.34 | AWH57: 105100 | AWI57: 118100 | AWJ57: 11700 | AWK57: 14500 | AWL57: 59800 | AWM57: 69700 | AWN57: 85500 | AWO57: 67300 | AWP57: 318900 | AWQ57: 287500 | AWR57: 369600 | AWS57: 672800 | AWT57: 245900 | AWU57: 1200 | AWV57: 9258563.2 | AWW57: 163492.29 | AWX57: 545425.06 | AWY57: 880470.9 | AWZ57: 90604.535 | AXA57: 142965.06 | AXB57: 116583.55 | AXC57: 20246.95 | AXD57: 115842.53 | AXE57: 99242.876 | AXF57: 182189.53 | AXG57: 402943 | AXH57: 169922.46 | AXI57: 131098.43 | AXJ57: 168285.62 | AXK57: 171179.51 | AXL57: 85995.942 | AXM57: 1297938.8 | AXN57: 365108.15 | AXO57: 1168971.7 | AXP57: 826302.08 | AXQ57: 375989 | AXR57: 689012.76 | AXS57: 68131.437 | AXT57: 35663.333 | AXU57: 27298.441 | AXV57: 86851.235 | AXW57: 234882.27 | AXX57: 173570.15 | AXY57: 99023.632 | AXZ57: 1298078.4 | AYA57: 710762.58 | AYB57: 388047.64 | AYC57: 563331.06 | AYD57: 40638.732 | AYE57: 916000 | AYF57: 14000 | AYG57: 126118.59 | AYH57: 267334.88 | AYI57: 60192.612 | AYJ57: 31856.052 | AYK57: 121179.95 | AYL57: 17975.215 | AYM57: 131550.58 | AYN57: 203678.51 | AYO57: 99145.448 | AYP57: 358728.15 | AYQ57: 155117.77 | AYR57: 544232.25 | AYS57: 141459.86 | AYT57: 170430.14 | AYU57: 35000 | AYV57: 927000 | AYW57: 54181.727 | AYX57: 873466.02 | AYY57: 628352.25 | AYZ57: 620000 | AZA57: 233162.96 | AZB57: 20581.235 | AZC57: 52271.2 | AZD57: 128984.61 | AZE57: 62000 | AZF57: 319000 | AZG57: 58000 | AZH57: 245000 | AZI57: 312000 | AZJ57: 439000 | AZK57: 223000 | AZL57: 551090.8 | AZM57: 133909.2 | AZN57: 2595872.3 | AZO57: 613452.36 | AZP57: 1844351.9 | AZQ57: 1447389.4 | AZR57: 97663.036 | AZS57: 612149.28 | AZT57: 2360517.8 | AZU57: 153474.3 | AZV57: 1071803.3 | AZW57: 935304.12 | AZX57: 541444.27 | AZY57: 2311673 | AZZ57: 1542364.3 | BAA57: 2576729.5 | BAB57: 1992901.4 | BAC57: 1136118.4 | BAD57: 634693.2 | BAE57: 7372055.2 | BAF57: 1158570.3 | BAG57: 5949207.5 | BAH57: 16162877 | BAI57: 9509521.8 | BAJ57: 2074020.9 | BAK57: 57910.858 | BAL57: 520895.77 | BAM57: 1316201.4 | BAN57: 2605061.8 | BAO57: 5665851.9 | BAP57: 1652020.6 | BAQ57: 15453803 | BAR57: 19891101 | BAS57: 2295723.3 | BAT57: 13652774 | BAU57: 7401565.2 | BAV57: 815862.75
A58: =SUM(A57:BAV57) -> 1.8294535e+09

Sheet LF
A1: World Development Indicators
A3: Country Code | B3: 1996
A4: ABW
A5: AND
A6: AFG | B6: 48.400002
A7: AGO | B7: 71.699997
A8: ALB | B8: 63.700001
A9: ARB | B9: 48.761749
A10: ARE | B10: 75.5
A11: ARG | B11: 57.900002
A12: ARM | B12: 65.800003
A13: ASM
A14: ATG
A15: AUS | B15: 63.599998
A16: AUT | B16: 58.299999
A17: AZE | B17: 63.700001
A18: BDI | B18: 86.800003
A19: BEL | B19: 50.400002
A20: BEN | B20: 72.900002
A21: BFA | B21: 83.300003
A22: BGD | B22: 72.900002
A23: BGR | B23: 53.700001
A24: BHR | B24: 65.400002
A25: BHS | B25: 73.099998
A26: BIH | B26: 46.700001
... A28: BLZ | B28: 61.200001
A29: BMU
A30: BOL | B30: 69.599998
A31: BRA | B31: 67.199997
A32: BRB | B32: 68.699997
A33: BRN | B33: 66.599998
A34: BTN | B34: 63.900002
A35: BWA | B35: 74.300003
A36: CAF | B36: 78.199997
A37: CAN | B37: 64.199997
A38: CEB | B38: 58.515247
A39: CHE | B39: 67.599998
A40: CHI
A41: CHL | B41: 55
A42: CHN | B42: 78.400002
...

Sheet UN
A1: World Development Indicators
A3: Country Code | B3: 1996
A4: ABW
A5: AND
A6: AFG | B6: 4.8000002
A7: AGO | B7: 6.8000002
A8: ALB | B8: 14.6
A9: ARB | B9: 13.190997
A10: ARE | B10: 2.5999999
A11: ARG | B11: 17.200001
A12: ARM | B12: 19.1
A13: ASM
A14: ATG
A15: AUS | B15: 8.5
A16: AUT | B16: 4.0999999
A17: AZE | B17: 4.6999998
A18: BDI | B18: 7.3000002
A19: BEL | B19: 9.5
A20: BEN | B20: 0.69999999
A21: BFA | B21: 2.4000001
A22: BGD | B22: 2.5
A23: BGR | B23: 13.5
A24: BHR | B24: 6.1999998
A25: BHS | B25: 11.5
A26: BIH | B26: 25.299999
... A28: BLZ | B28: 13.8
A29: BMU
A30: BOL | B30: 5.1999998
A31: BRA | B31: 6.8000002
A32: BRB | B32: 14.7
A33: BRN | B33: 4.0999999
A34: BTN | B34: 2.5
A35: BWA | B35: 21.5
A36: CAF | B36: 7.0999999
A37: CAN | B37: 9.6000004
A38: CEB | B38: 9.9452203
A39: CHE | B39: 3.7
A40: CHI
A41: CHL | B41: 6.3000002
A42: CHN | B42: 4.5999999
...
