Workbook

Sheet Emprego - WorldBank
B1: 1995 | C1: 1996 | D1: 1997 | E1: 1998 | F1: 1999 | G1: 2000 | H1: 2001 | I1: 2002 | J1: 2003 | K1: 2004 | L1: 2005 | M1: 2006 | N1: 2007 | O1: 2008 | P1: 2009 | Q1: 2010 | R1: 2011 | S1: 2012 | T1: 2013 | U1: 2014
A2: AUS | B2: =VLOOKUP($A2,[1]Data!$B$1:$BK$65536,B$1-1956,FALSE)*VLOOKUP($A2,[2]Data!$B$1:$BK$65536,B$1-1956,FALSE)/100 -> 10534169 | C2: =VLOOKUP($A2,[1]Data!$B$1:$BK$65536,C$1-1956,FALSE)*VLOOKUP($A2,[2]Data!$B$1:$BK$65536,C$1-1956,FALSE)/100 -> 10667622 | D2: =VLOOKUP($A2,[1]Data!$B$1:$BK$65536,D$1-1956,FALSE)*VLOOKUP($A2,[2]Data!$B$1:$BK$65536,D$1-1956,FALSE)/100 -> 10743749 | E2: =VLOOKUP($A2,[1]Data!$B$1:$BK$65536,E$1-1956,FALSE)*VLOOKUP($A2,[2]Data!$B$1:$BK$65536,E$1-1956,FALSE)/100 -> 10920675 | F2: =VLOOKUP($A2,[1]Data!$B$1:$BK$65536,F$1-1956,FALSE)*VLOOKUP($A2,[2]Data!$B$1:$BK$65536,F$1-1956,FALSE)/100 -> 11104452 | G2: =VLOOKUP($A2,[1]Data!$B$1:$BK$65536,G$1-1956,FALSE)*VLOOKUP($A2,[2]Data!$B$1:$BK$65536,G$1-1956,FALSE)/100 -> 11375349 | H2: =VLOOKUP($A2,[1]Data!$B$1:$BK$65536,H$1-1956,FALSE)*VLOOKUP($A2,[2]Data!$B$1:$BK$65536,H$1-1956,FALSE)/100 -> 11506861 | I2: =VLOOKUP($A2,[1]Data!$B$1:$BK$65536,I$1-1956,FALSE)*VLOOKUP($A2,[2]Data!$B$1:$BK$65536,I$1-1956,FALSE)/100 -> 11705946 | ... U2: =VLOOKUP($A2,[1]Data!$B$1:$BK$65536,U$1-1956,FALSE)*VLOOKUP($A2,[2]Data!$B$1:$BK$65536,U$1-1956,FALSE)/100 -> 14300214
A3: AUT | B3: =VLOOKUP($A3,[1]Data!$B$1:$BK$65536,B$1-1956,FALSE)*VLOOKUP($A3,[2]Data!$B$1:$BK$65536,B$1-1956,FALSE)/100 -> 4489584.9 | C3: =VLOOKUP($A3,[1]Data!$B$1:$BK$65536,C$1-1956,FALSE)*VLOOKUP($A3,[2]Data!$B$1:$BK$65536,C$1-1956,FALSE)/100 -> 4412558.8 | D3: =VLOOKUP($A3,[1]Data!$B$1:$BK$65536,D$1-1956,FALSE)*VLOOKUP($A3,[2]Data!$B$1:$BK$65536,D$1-1956,FALSE)/100 -> 4398279.1 | E3: =VLOOKUP($A3,[1]Data!$B$1:$BK$65536,E$1-1956,FALSE)*VLOOKUP($A3,[2]Data!$B$1:$BK$65536,E$1-1956,FALSE)/100 -> 4407495.1 | F3: =VLOOKUP($A3,[1]Data!$B$1:$BK$65536,F$1-1956,FALSE)*VLOOKUP($A3,[2]Data!$B$1:$BK$65536,F$1-1956,FALSE)/100 -> 4465551.3 | G3: =VLOOKUP($A3,[1]Data!$B$1:$BK$65536,G$1-1956,FALSE)*VLOOKUP($A3,[2]Data!$B$1:$BK$65536,G$1-1956,FALSE)/100 -> 4468210.5 | H3: =VLOOKUP($A3,[1]Data!$B$1:$BK$65536,H$1-1956,FALSE)*VLOOKUP($A3,[2]Data!$B$1:$BK$65536,H$1-1956,FALSE)/100 -> 4473927.7 | I3: =VLOOKUP($A3,[1]Data!$B$1:$BK$65536,I$1-1956,FALSE)*VLOOKUP($A3,[2]Data!$B$1:$BK$65536,I$1-1956,FALSE)/100 -> 4524522.1 | ... U3: =VLOOKUP($A3,[1]Data!$B$1:$BK$65536,U$1-1956,FALSE)*VLOOKUP($A3,[2]Data!$B$1:$BK$65536,U$1-1956,FALSE)/100 -> 4852450
A4: BEL | B4: =VLOOKUP($A4,[1]Data!$B$1:$BK$65536,B$1-1956,FALSE)*VLOOKUP($A4,[2]Data!$B$1:$BK$65536,B$1-1956,FALSE)/100 -> 4631711.8 | C4: =VLOOKUP($A4,[1]Data!$B$1:$BK$65536,C$1-1956,FALSE)*VLOOKUP($A4,[2]Data!$B$1:$BK$65536,C$1-1956,FALSE)/100 -> 4626348.1 | D4: =VLOOKUP($A4,[1]Data!$B$1:$BK$65536,D$1-1956,FALSE)*VLOOKUP($A4,[2]Data!$B$1:$BK$65536,D$1-1956,FALSE)/100 -> 4672886 | E4: =VLOOKUP($A4,[1]Data!$B$1:$BK$65536,E$1-1956,FALSE)*VLOOKUP($A4,[2]Data!$B$1:$BK$65536,E$1-1956,FALSE)/100 -> 4689506.7 | F4: =VLOOKUP($A4,[1]Data!$B$1:$BK$65536,F$1-1956,FALSE)*VLOOKUP($A4,[2]Data!$B$1:$BK$65536,F$1-1956,FALSE)/100 -> 4843334.3 | G4: =VLOOKUP($A4,[1]Data!$B$1:$BK$65536,G$1-1956,FALSE)*VLOOKUP($A4,[2]Data!$B$1:$BK$65536,G$1-1956,FALSE)/100 -> 4998714.6 | H4: =VLOOKUP($A4,[1]Data!$B$1:$BK$65536,H$1-1956,FALSE)*VLOOKUP($A4,[2]Data!$B$1:$BK$65536,H$1-1956,FALSE)/100 -> 4895173.1 | I4: =VLOOKUP($A4,[1]Data!$B$1:$BK$65536,I$1-1956,FALSE)*VLOOKUP($A4,[2]Data!$B$1:$BK$65536,I$1-1956,FALSE)/100 -> 4899910.1 | ... U4: =VLOOKUP($A4,[1]Data!$B$1:$BK$65536,U$1-1956,FALSE)*VLOOKUP($A4,[2]Data!$B$1:$BK$65536,U$1-1956,FALSE)/100 -> 5490868.7
A5: BGR | B5: =VLOOKUP($A5,[1]Data!$B$1:$BK$65536,B$1-1956,FALSE)*VLOOKUP($A5,[2]Data!$B$1:$BK$65536,B$1-1956,FALSE)/100 -> 3983467.1 | C5: =VLOOKUP($A5,[1]Data!$B$1:$BK$65536,C$1-1956,FALSE)*VLOOKUP($A5,[2]Data!$B$1:$BK$65536,C$1-1956,FALSE)/100 -> 3893564.4 | D5: =VLOOKUP($A5,[1]Data!$B$1:$BK$65536,D$1-1956,FALSE)*VLOOKUP($A5,[2]Data!$B$1:$BK$65536,D$1-1956,FALSE)/100 -> 3802937.3 | E5: =VLOOKUP($A5,[1]Data!$B$1:$BK$65536,E$1-1956,FALSE)*VLOOKUP($A5,[2]Data!$B$1:$BK$65536,E$1-1956,FALSE)/100 -> 3772608.2 | F5: =VLOOKUP($A5,[1]Data!$B$1:$BK$65536,F$1-1956,FALSE)*VLOOKUP($A5,[2]Data!$B$1:$BK$65536,F$1-1956,FALSE)/100 -> 3596992.1 | G5: =VLOOKUP($A5,[1]Data!$B$1:$BK$65536,G$1-1956,FALSE)*VLOOKUP($A5,[2]Data!$B$1:$BK$65536,G$1-1956,FALSE)/100 -> 3414151.3 | H5: =VLOOKUP($A5,[1]Data!$B$1:$BK$65536,H$1-1956,FALSE)*VLOOKUP($A5,[2]Data!$B$1:$BK$65536,H$1-1956,FALSE)/100 -> 3312260.7 | I5: =VLOOKUP($A5,[1]Data!$B$1:$BK$65536,I$1-1956,FALSE)*VLOOKUP($A5,[2]Data!$B$1:$BK$65536,I$1-1956,FALSE)/100 -> 3283535.3 | ... U5: =VLOOKUP($A5,[1]Data!$B$1:$BK$65536,U$1-1956,FALSE)*VLOOKUP($A5,[2]Data!$B$1:$BK$65536,U$1-1956,FALSE)/100 -> 3464817.5
A6: BRA | B6: =VLOOKUP($A6,[1]Data!$B$1:$BK$65536,B$1-1956,FALSE)*VLOOKUP($A6,[2]Data!$B$1:$BK$65536,B$1-1956,FALSE)/100 -> 96690236 | C6: =VLOOKUP($A6,[1]Data!$B$1:$BK$65536,C$1-1956,FALSE)*VLOOKUP($A6,[2]Data!$B$1:$BK$65536,C$1-1956,FALSE)/100 -> 95282274 | D6: =VLOOKUP($A6,[1]Data!$B$1:$BK$65536,D$1-1956,FALSE)*VLOOKUP($A6,[2]Data!$B$1:$BK$65536,D$1-1956,FALSE)/100 -> 96867540 | E6: =VLOOKUP($A6,[1]Data!$B$1:$BK$65536,E$1-1956,FALSE)*VLOOKUP($A6,[2]Data!$B$1:$BK$65536,E$1-1956,FALSE)/100 -> 97319208 | F6: =VLOOKUP($A6,[1]Data!$B$1:$BK$65536,F$1-1956,FALSE)*VLOOKUP($A6,[2]Data!$B$1:$BK$65536,F$1-1956,FALSE)/100 -> 98812695 | G6: =VLOOKUP($A6,[1]Data!$B$1:$BK$65536,G$1-1956,FALSE)*VLOOKUP($A6,[2]Data!$B$1:$BK$65536,G$1-1956,FALSE)/100 -> 1.0094666e+08 | H6: =VLOOKUP($A6,[1]Data!$B$1:$BK$65536,H$1-1956,FALSE)*VLOOKUP($A6,[2]Data!$B$1:$BK$65536,H$1-1956,FALSE)/100 -> 1.0303596e+08 | I6: =VLOOKUP($A6,[1]Data!$B$1:$BK$65536,I$1-1956,FALSE)*VLOOKUP($A6,[2]Data!$B$1:$BK$65536,I$1-1956,FALSE)/100 -> 1.0581044e+08 | ... U6: =VLOOKUP($A6,[1]Data!$B$1:$BK$65536,U$1-1956,FALSE)*VLOOKUP($A6,[2]Data!$B$1:$BK$65536,U$1-1956,FALSE)/100 -> 1.2093032e+08
A7: CAN | B7: =VLOOKUP($A7,[1]Data!$B$1:$BK$65536,B$1-1956,FALSE)*VLOOKUP($A7,[2]Data!$B$1:$BK$65536,B$1-1956,FALSE)/100 -> 17081782 | C7: =VLOOKUP($A7,[1]Data!$B$1:$BK$65536,C$1-1956,FALSE)*VLOOKUP($A7,[2]Data!$B$1:$BK$65536,C$1-1956,FALSE)/100 -> 17186363 | D7: =VLOOKUP($A7,[1]Data!$B$1:$BK$65536,D$1-1956,FALSE)*VLOOKUP($A7,[2]Data!$B$1:$BK$65536,D$1-1956,FALSE)/100 -> 17511129 | E7: =VLOOKUP($A7,[1]Data!$B$1:$BK$65536,E$1-1956,FALSE)*VLOOKUP($A7,[2]Data!$B$1:$BK$65536,E$1-1956,FALSE)/100 -> 17888954 | F7: =VLOOKUP($A7,[1]Data!$B$1:$BK$65536,F$1-1956,FALSE)*VLOOKUP($A7,[2]Data!$B$1:$BK$65536,F$1-1956,FALSE)/100 -> 18283029 | G7: =VLOOKUP($A7,[1]Data!$B$1:$BK$65536,G$1-1956,FALSE)*VLOOKUP($A7,[2]Data!$B$1:$BK$65536,G$1-1956,FALSE)/100 -> 18660300 | H7: =VLOOKUP($A7,[1]Data!$B$1:$BK$65536,H$1-1956,FALSE)*VLOOKUP($A7,[2]Data!$B$1:$BK$65536,H$1-1956,FALSE)/100 -> 18814488 | I7: =VLOOKUP($A7,[1]Data!$B$1:$BK$65536,I$1-1956,FALSE)*VLOOKUP($A7,[2]Data!$B$1:$BK$65536,I$1-1956,FALSE)/100 -> 19205540 | ... U7: =VLOOKUP($A7,[1]Data!$B$1:$BK$65536,U$1-1956,FALSE)*VLOOKUP($A7,[2]Data!$B$1:$BK$65536,U$1-1956,FALSE)/100 -> 21693380
A8: CHN | B8: =VLOOKUP($A8,[1]Data!$B$1:$BK$65536,B$1-1956,FALSE)*VLOOKUP($A8,[2]Data!$B$1:$BK$65536,B$1-1956,FALSE)/100 -> 9.2043689e+08 | C8: =VLOOKUP($A8,[1]Data!$B$1:$BK$65536,C$1-1956,FALSE)*VLOOKUP($A8,[2]Data!$B$1:$BK$65536,C$1-1956,FALSE)/100 -> 9.2699389e+08 | D8: =VLOOKUP($A8,[1]Data!$B$1:$BK$65536,D$1-1956,FALSE)*VLOOKUP($A8,[2]Data!$B$1:$BK$65536,D$1-1956,FALSE)/100 -> 9.3280278e+08 | E8: =VLOOKUP($A8,[1]Data!$B$1:$BK$65536,E$1-1956,FALSE)*VLOOKUP($A8,[2]Data!$B$1:$BK$65536,E$1-1956,FALSE)/100 -> 9.3843088e+08 | F8: =VLOOKUP($A8,[1]Data!$B$1:$BK$65536,F$1-1956,FALSE)*VLOOKUP($A8,[2]Data!$B$1:$BK$65536,F$1-1956,FALSE)/100 -> 9.4248266e+08 | G8: =VLOOKUP($A8,[1]Data!$B$1:$BK$65536,G$1-1956,FALSE)*VLOOKUP($A8,[2]Data!$B$1:$BK$65536,G$1-1956,FALSE)/100 -> 9.4508976e+08 | H8: =VLOOKUP($A8,[1]Data!$B$1:$BK$65536,H$1-1956,FALSE)*VLOOKUP($A8,[2]Data!$B$1:$BK$65536,H$1-1956,FALSE)/100 -> 9.3788759e+08 | I8: =VLOOKUP($A8,[1]Data!$B$1:$BK$65536,I$1-1956,FALSE)*VLOOKUP($A8,[2]Data!$B$1:$BK$65536,I$1-1956,FALSE)/100 -> 9.2999297e+08 | ... U8: =VLOOKUP($A8,[1]Data!$B$1:$BK$65536,U$1-1956,FALSE)*VLOOKUP($A8,[2]Data!$B$1:$BK$65536,U$1-1956,FALSE)/100 -> 9.1316046e+08
A9: CYP | B9: =VLOOKUP($A9,[1]Data!$B$1:$BK$65536,B$1-1956,FALSE)*VLOOKUP($A9,[2]Data!$B$1:$BK$65536,B$1-1956,FALSE)/100 -> 494608.13 | C9: =VLOOKUP($A9,[1]Data!$B$1:$BK$65536,C$1-1956,FALSE)*VLOOKUP($A9,[2]Data!$B$1:$BK$65536,C$1-1956,FALSE)/100 -> 504934.58 | D9: =VLOOKUP($A9,[1]Data!$B$1:$BK$65536,D$1-1956,FALSE)*VLOOKUP($A9,[2]Data!$B$1:$BK$65536,D$1-1956,FALSE)/100 -> 516364.41 | E9: =VLOOKUP($A9,[1]Data!$B$1:$BK$65536,E$1-1956,FALSE)*VLOOKUP($A9,[2]Data!$B$1:$BK$65536,E$1-1956,FALSE)/100 -> 520513.58 | F9: =VLOOKUP($A9,[1]Data!$B$1:$BK$65536,F$1-1956,FALSE)*VLOOKUP($A9,[2]Data!$B$1:$BK$65536,F$1-1956,FALSE)/100 -> 528124.02 | G9: =VLOOKUP($A9,[1]Data!$B$1:$BK$65536,G$1-1956,FALSE)*VLOOKUP($A9,[2]Data!$B$1:$BK$65536,G$1-1956,FALSE)/100 -> 545193.33 | H9: =VLOOKUP($A9,[1]Data!$B$1:$BK$65536,H$1-1956,FALSE)*VLOOKUP($A9,[2]Data!$B$1:$BK$65536,H$1-1956,FALSE)/100 -> 572708.6 | I9: =VLOOKUP($A9,[1]Data!$B$1:$BK$65536,I$1-1956,FALSE)*VLOOKUP($A9,[2]Data!$B$1:$BK$65536,I$1-1956,FALSE)/100 -> 585914.62 | ... U9: =VLOOKUP($A9,[1]Data!$B$1:$BK$65536,U$1-1956,FALSE)*VLOOKUP($A9,[2]Data!$B$1:$BK$65536,U$1-1956,FALSE)/100 -> 611529.16
A10: CZE | B10: =VLOOKUP($A10,[1]Data!$B$1:$BK$65536,B$1-1956,FALSE)*VLOOKUP($A10,[2]Data!$B$1:$BK$65536,B$1-1956,FALSE)/100 -> 6086263.1 | C10: =VLOOKUP($A10,[1]Data!$B$1:$BK$65536,C$1-1956,FALSE)*VLOOKUP($A10,[2]Data!$B$1:$BK$65536,C$1-1956,FALSE)/100 -> 6052570.7 | D10: =VLOOKUP($A10,[1]Data!$B$1:$BK$65536,D$1-1956,FALSE)*VLOOKUP($A10,[2]Data!$B$1:$BK$65536,D$1-1956,FALSE)/100 -> 5967637.6 | E10: =VLOOKUP($A10,[1]Data!$B$1:$BK$65536,E$1-1956,FALSE)*VLOOKUP($A10,[2]Data!$B$1:$BK$65536,E$1-1956,FALSE)/100 -> 5859351.1 | F10: =VLOOKUP($A10,[1]Data!$B$1:$BK$65536,F$1-1956,FALSE)*VLOOKUP($A10,[2]Data!$B$1:$BK$65536,F$1-1956,FALSE)/100 -> 5701886.1 | G10: =VLOOKUP($A10,[1]Data!$B$1:$BK$65536,G$1-1956,FALSE)*VLOOKUP($A10,[2]Data!$B$1:$BK$65536,G$1-1956,FALSE)/100 -> 5625619.8 | H10: =VLOOKUP($A10,[1]Data!$B$1:$BK$65536,H$1-1956,FALSE)*VLOOKUP($A10,[2]Data!$B$1:$BK$65536,H$1-1956,FALSE)/100 -> 5615863.3 | I10: =VLOOKUP($A10,[1]Data!$B$1:$BK$65536,I$1-1956,FALSE)*VLOOKUP($A10,[2]Data!$B$1:$BK$65536,I$1-1956,FALSE)/100 -> 5652660.5 | ... U10: =VLOOKUP($A10,[1]Data!$B$1:$BK$65536,U$1-1956,FALSE)*VLOOKUP($A10,[2]Data!$B$1:$BK$65536,U$1-1956,FALSE)/100 -> 5874090.7
A11: DEU | B11: =VLOOKUP($A11,[1]Data!$B$1:$BK$65536,B$1-1956,FALSE)*VLOOKUP($A11,[2]Data!$B$1:$BK$65536,B$1-1956,FALSE)/100 -> 43651201 | C11: =VLOOKUP($A11,[1]Data!$B$1:$BK$65536,C$1-1956,FALSE)*VLOOKUP($A11,[2]Data!$B$1:$BK$65536,C$1-1956,FALSE)/100 -> 43290350 | D11: =VLOOKUP($A11,[1]Data!$B$1:$BK$65536,D$1-1956,FALSE)*VLOOKUP($A11,[2]Data!$B$1:$BK$65536,D$1-1956,FALSE)/100 -> 42996063 | E11: =VLOOKUP($A11,[1]Data!$B$1:$BK$65536,E$1-1956,FALSE)*VLOOKUP($A11,[2]Data!$B$1:$BK$65536,E$1-1956,FALSE)/100 -> 43026371 | F11: =VLOOKUP($A11,[1]Data!$B$1:$BK$65536,F$1-1956,FALSE)*VLOOKUP($A11,[2]Data!$B$1:$BK$65536,F$1-1956,FALSE)/100 -> 43642848 | G11: =VLOOKUP($A11,[1]Data!$B$1:$BK$65536,G$1-1956,FALSE)*VLOOKUP($A11,[2]Data!$B$1:$BK$65536,G$1-1956,FALSE)/100 -> 43952740 | H11: =VLOOKUP($A11,[1]Data!$B$1:$BK$65536,H$1-1956,FALSE)*VLOOKUP($A11,[2]Data!$B$1:$BK$65536,H$1-1956,FALSE)/100 -> 44019328 | I11: =VLOOKUP($A11,[1]Data!$B$1:$BK$65536,I$1-1956,FALSE)*VLOOKUP($A11,[2]Data!$B$1:$BK$65536,I$1-1956,FALSE)/100 -> 43671885 | ... U11: =VLOOKUP($A11,[1]Data!$B$1:$BK$65536,U$1-1956,FALSE)*VLOOKUP($A11,[2]Data!$B$1:$BK$65536,U$1-1956,FALSE)/100 -> 46354384
A12: DNK | B12: =VLOOKUP($A12,[1]Data!$B$1:$BK$65536,B$1-1956,FALSE)*VLOOKUP($A12,[2]Data!$B$1:$BK$65536,B$1-1956,FALSE)/100 -> 3180896.4 | C12: =VLOOKUP($A12,[1]Data!$B$1:$BK$65536,C$1-1956,FALSE)*VLOOKUP($A12,[2]Data!$B$1:$BK$65536,C$1-1956,FALSE)/100 -> 3206422.6 | D12: =VLOOKUP($A12,[1]Data!$B$1:$BK$65536,D$1-1956,FALSE)*VLOOKUP($A12,[2]Data!$B$1:$BK$65536,D$1-1956,FALSE)/100 -> 3288638.6 | E12: =VLOOKUP($A12,[1]Data!$B$1:$BK$65536,E$1-1956,FALSE)*VLOOKUP($A12,[2]Data!$B$1:$BK$65536,E$1-1956,FALSE)/100 -> 3297314.8 | F12: =VLOOKUP($A12,[1]Data!$B$1:$BK$65536,F$1-1956,FALSE)*VLOOKUP($A12,[2]Data!$B$1:$BK$65536,F$1-1956,FALSE)/100 -> 3341185.1 | G12: =VLOOKUP($A12,[1]Data!$B$1:$BK$65536,G$1-1956,FALSE)*VLOOKUP($A12,[2]Data!$B$1:$BK$65536,G$1-1956,FALSE)/100 -> 3354613.8 | H12: =VLOOKUP($A12,[1]Data!$B$1:$BK$65536,H$1-1956,FALSE)*VLOOKUP($A12,[2]Data!$B$1:$BK$65536,H$1-1956,FALSE)/100 -> 3359045.9 | I12: =VLOOKUP($A12,[1]Data!$B$1:$BK$65536,I$1-1956,FALSE)*VLOOKUP($A12,[2]Data!$B$1:$BK$65536,I$1-1956,FALSE)/100 -> 3401459 | ... U12: =VLOOKUP($A12,[1]Data!$B$1:$BK$65536,U$1-1956,FALSE)*VLOOKUP($A12,[2]Data!$B$1:$BK$65536,U$1-1956,FALSE)/100 -> 3272933.3
A13: ESP | B13: =VLOOKUP($A13,[1]Data!$B$1:$BK$65536,B$1-1956,FALSE)*VLOOKUP($A13,[2]Data!$B$1:$BK$65536,B$1-1956,FALSE)/100 -> 15357318 | C13: =VLOOKUP($A13,[1]Data!$B$1:$BK$65536,C$1-1956,FALSE)*VLOOKUP($A13,[2]Data!$B$1:$BK$65536,C$1-1956,FALSE)/100 -> 15633233 | D13: =VLOOKUP($A13,[1]Data!$B$1:$BK$65536,D$1-1956,FALSE)*VLOOKUP($A13,[2]Data!$B$1:$BK$65536,D$1-1956,FALSE)/100 -> 16145131 | E13: =VLOOKUP($A13,[1]Data!$B$1:$BK$65536,E$1-1956,FALSE)*VLOOKUP($A13,[2]Data!$B$1:$BK$65536,E$1-1956,FALSE)/100 -> 16745449 | F13: =VLOOKUP($A13,[1]Data!$B$1:$BK$65536,F$1-1956,FALSE)*VLOOKUP($A13,[2]Data!$B$1:$BK$65536,F$1-1956,FALSE)/100 -> 17660373 | G13: =VLOOKUP($A13,[1]Data!$B$1:$BK$65536,G$1-1956,FALSE)*VLOOKUP($A13,[2]Data!$B$1:$BK$65536,G$1-1956,FALSE)/100 -> 18480285 | H13: =VLOOKUP($A13,[1]Data!$B$1:$BK$65536,H$1-1956,FALSE)*VLOOKUP($A13,[2]Data!$B$1:$BK$65536,H$1-1956,FALSE)/100 -> 19097568 | I13: =VLOOKUP($A13,[1]Data!$B$1:$BK$65536,I$1-1956,FALSE)*VLOOKUP($A13,[2]Data!$B$1:$BK$65536,I$1-1956,FALSE)/100 -> 19778183 | ... U13: =VLOOKUP($A13,[1]Data!$B$1:$BK$65536,U$1-1956,FALSE)*VLOOKUP($A13,[2]Data!$B$1:$BK$65536,U$1-1956,FALSE)/100 -> 20583129
... A39: TUR | B39: =VLOOKUP($A39,[1]Data!$B$1:$BK$65536,B$1-1956,FALSE)*VLOOKUP($A39,[2]Data!$B$1:$BK$65536,B$1-1956,FALSE)/100 -> 28883535 | C39: =VLOOKUP($A39,[1]Data!$B$1:$BK$65536,C$1-1956,FALSE)*VLOOKUP($A39,[2]Data!$B$1:$BK$65536,C$1-1956,FALSE)/100 -> 29402640 | D39: =VLOOKUP($A39,[1]Data!$B$1:$BK$65536,D$1-1956,FALSE)*VLOOKUP($A39,[2]Data!$B$1:$BK$65536,D$1-1956,FALSE)/100 -> 29073618 | E39: =VLOOKUP($A39,[1]Data!$B$1:$BK$65536,E$1-1956,FALSE)*VLOOKUP($A39,[2]Data!$B$1:$BK$65536,E$1-1956,FALSE)/100 -> 29603222 | F39: =VLOOKUP($A39,[1]Data!$B$1:$BK$65536,F$1-1956,FALSE)*VLOOKUP($A39,[2]Data!$B$1:$BK$65536,F$1-1956,FALSE)/100 -> 29736004 | G39: =VLOOKUP($A39,[1]Data!$B$1:$BK$65536,G$1-1956,FALSE)*VLOOKUP($A39,[2]Data!$B$1:$BK$65536,G$1-1956,FALSE)/100 -> 28853971 | H39: =VLOOKUP($A39,[1]Data!$B$1:$BK$65536,H$1-1956,FALSE)*VLOOKUP($A39,[2]Data!$B$1:$BK$65536,H$1-1956,FALSE)/100 -> 28583522 | I39: =VLOOKUP($A39,[1]Data!$B$1:$BK$65536,I$1-1956,FALSE)*VLOOKUP($A39,[2]Data!$B$1:$BK$65536,I$1-1956,FALSE)/100 -> 28189703 | ... U39: =VLOOKUP($A39,[1]Data!$B$1:$BK$65536,U$1-1956,FALSE)*VLOOKUP($A39,[2]Data!$B$1:$BK$65536,U$1-1956,FALSE)/100 -> 34877157
A40: TWN | B40: =B60 -> 9068000 | C40: =C60 -> 9176000 | D40: =D60 -> 9289000 | E40: =E60 -> 9385000 | F40: =F60 -> 9491000 | G40: =G60 -> 9383000 | H40: =H60 -> 9454000 | I40: =I60 -> 9573000 | ... U40: =U60 -> 11198000
A41: USA | B41: =VLOOKUP($A41,[1]Data!$B$1:$BK$65536,B$1-1956,FALSE)*VLOOKUP($A41,[2]Data!$B$1:$BK$65536,B$1-1956,FALSE)/100 -> 1.6537727e+08 | C41: =VLOOKUP($A41,[1]Data!$B$1:$BK$65536,C$1-1956,FALSE)*VLOOKUP($A41,[2]Data!$B$1:$BK$65536,C$1-1956,FALSE)/100 -> 1.6811263e+08 | D41: =VLOOKUP($A41,[1]Data!$B$1:$BK$65536,D$1-1956,FALSE)*VLOOKUP($A41,[2]Data!$B$1:$BK$65536,D$1-1956,FALSE)/100 -> 1.7180117e+08 | E41: =VLOOKUP($A41,[1]Data!$B$1:$BK$65536,E$1-1956,FALSE)*VLOOKUP($A41,[2]Data!$B$1:$BK$65536,E$1-1956,FALSE)/100 -> 1.7463489e+08 | F41: =VLOOKUP($A41,[1]Data!$B$1:$BK$65536,F$1-1956,FALSE)*VLOOKUP($A41,[2]Data!$B$1:$BK$65536,F$1-1956,FALSE)/100 -> 1.7735783e+08 | G41: =VLOOKUP($A41,[1]Data!$B$1:$BK$65536,G$1-1956,FALSE)*VLOOKUP($A41,[2]Data!$B$1:$BK$65536,G$1-1956,FALSE)/100 -> 1.7992086e+08 | H41: =VLOOKUP($A41,[1]Data!$B$1:$BK$65536,H$1-1956,FALSE)*VLOOKUP($A41,[2]Data!$B$1:$BK$65536,H$1-1956,FALSE)/100 -> 1.7931386e+08 | I41: =VLOOKUP($A41,[1]Data!$B$1:$BK$65536,I$1-1956,FALSE)*VLOOKUP($A41,[2]Data!$B$1:$BK$65536,I$1-1956,FALSE)/100 -> 1.7802561e+08 | ... U41: =VLOOKUP($A41,[1]Data!$B$1:$BK$65536,U$1-1956,FALSE)*VLOOKUP($A41,[2]Data!$B$1:$BK$65536,U$1-1956,FALSE)/100 -> 1.8576047e+08
A42: WLD | B42: =VLOOKUP($A42,[1]Data!$B$1:$BK$65536,B$1-1956,FALSE)*VLOOKUP($A42,[2]Data!$B$1:$BK$65536,B$1-1956,FALSE)/100 -> 3.5125249e+09 | C42: =VLOOKUP($A42,[1]Data!$B$1:$BK$65536,C$1-1956,FALSE)*VLOOKUP($A42,[2]Data!$B$1:$BK$65536,C$1-1956,FALSE)/100 -> 3.5528667e+09 | D42: =VLOOKUP($A42,[1]Data!$B$1:$BK$65536,D$1-1956,FALSE)*VLOOKUP($A42,[2]Data!$B$1:$BK$65536,D$1-1956,FALSE)/100 -> 3.5983354e+09 | E42: =VLOOKUP($A42,[1]Data!$B$1:$BK$65536,E$1-1956,FALSE)*VLOOKUP($A42,[2]Data!$B$1:$BK$65536,E$1-1956,FALSE)/100 -> 3.6358222e+09 | F42: =VLOOKUP($A42,[1]Data!$B$1:$BK$65536,F$1-1956,FALSE)*VLOOKUP($A42,[2]Data!$B$1:$BK$65536,F$1-1956,FALSE)/100 -> 3.6804878e+09 | G42: =VLOOKUP($A42,[1]Data!$B$1:$BK$65536,G$1-1956,FALSE)*VLOOKUP($A42,[2]Data!$B$1:$BK$65536,G$1-1956,FALSE)/100 -> 3.726598e+09 | H42: =VLOOKUP($A42,[1]Data!$B$1:$BK$65536,H$1-1956,FALSE)*VLOOKUP($A42,[2]Data!$B$1:$BK$65536,H$1-1956,FALSE)/100 -> 3.7548925e+09 | I42: =VLOOKUP($A42,[1]Data!$B$1:$BK$65536,I$1-1956,FALSE)*VLOOKUP($A42,[2]Data!$B$1:$BK$65536,I$1-1956,FALSE)/100 -> 3.7784471e+09 | ... U42: =VLOOKUP($A42,[1]Data!$B$1:$BK$65536,U$1-1956,FALSE)*VLOOKUP($A42,[2]Data!$B$1:$BK$65536,U$1-1956,FALSE)/100 -> 4.2106099e+09
A44: SOMA-14 | B44: =SUM(B2:B41) -> 2.3819196e+09 | C44: =SUM(C2:C41) -> 2.4015151e+09 | D44: =SUM(D2:D41) -> 2.4242519e+09 | E44: =SUM(E2:E41) -> 2.4433032e+09 | F44: =SUM(F2:F41) -> 2.4691878e+09 | G44: =SUM(G2:G41) -> 2.4910242e+09 | H44: =SUM(H2:H41) -> 2.4974756e+09 | I44: =SUM(I2:I41) -> 2.5012892e+09 | ... U44: =SUM(U2:U41) -> 2.6115955e+09
A45: ROW-14 | B45: =B42-SUM(B2:B41) -> 1.1306054e+09 | C45: =C42-SUM(C2:C41) -> 1.1513516e+09 | D45: =D42-SUM(D2:D41) -> 1.1740835e+09 | E45: =E42-SUM(E2:E41) -> 1.1925191e+09 | F45: =F42-SUM(F2:F41) -> 1.2113e+09 | G45: =G42-SUM(G2:G41) -> 1.2355738e+09 | H45: =H42-SUM(H2:H41) -> 1.257417e+09 | I45: =I42-SUM(I2:I41) -> 1.2771579e+09 | ... U45: =U42-SUM(U2:U41) -> 1.5990144e+09
A48: CHE | B48: =VLOOKUP($A48,[1]Data!$B$1:$BK$65536,B$1-1956,FALSE)*VLOOKUP($A48,[2]Data!$B$1:$BK$65536,B$1-1956,FALSE)/100 -> 4565322.5 | C48: =VLOOKUP($A48,[1]Data!$B$1:$BK$65536,C$1-1956,FALSE)*VLOOKUP($A48,[2]Data!$B$1:$BK$65536,C$1-1956,FALSE)/100 -> 4601228.7 | D48: =VLOOKUP($A48,[1]Data!$B$1:$BK$65536,D$1-1956,FALSE)*VLOOKUP($A48,[2]Data!$B$1:$BK$65536,D$1-1956,FALSE)/100 -> 4577803.1 | E48: =VLOOKUP($A48,[1]Data!$B$1:$BK$65536,E$1-1956,FALSE)*VLOOKUP($A48,[2]Data!$B$1:$BK$65536,E$1-1956,FALSE)/100 -> 4655842.1 | F48: =VLOOKUP($A48,[1]Data!$B$1:$BK$65536,F$1-1956,FALSE)*VLOOKUP($A48,[2]Data!$B$1:$BK$65536,F$1-1956,FALSE)/100 -> 4698888.8 | G48: =VLOOKUP($A48,[1]Data!$B$1:$BK$65536,G$1-1956,FALSE)*VLOOKUP($A48,[2]Data!$B$1:$BK$65536,G$1-1956,FALSE)/100 -> 4713945.5 | H48: =VLOOKUP($A48,[1]Data!$B$1:$BK$65536,H$1-1956,FALSE)*VLOOKUP($A48,[2]Data!$B$1:$BK$65536,H$1-1956,FALSE)/100 -> 4778933.4 | I48: =VLOOKUP($A48,[1]Data!$B$1:$BK$65536,I$1-1956,FALSE)*VLOOKUP($A48,[2]Data!$B$1:$BK$65536,I$1-1956,FALSE)/100 -> 4790161.9 | ... U48: =VLOOKUP($A48,[1]Data!$B$1:$BK$65536,U$1-1956,FALSE)*VLOOKUP($A48,[2]Data!$B$1:$BK$65536,U$1-1956,FALSE)/100 -> 5296827.4
A49: HRV | B49: =VLOOKUP($A49,[1]Data!$B$1:$BK$65536,B$1-1956,FALSE)*VLOOKUP($A49,[2]Data!$B$1:$BK$65536,B$1-1956,FALSE)/100 -> 2296847.9 | C49: =VLOOKUP($A49,[1]Data!$B$1:$BK$65536,C$1-1956,FALSE)*VLOOKUP($A49,[2]Data!$B$1:$BK$65536,C$1-1956,FALSE)/100 -> 2266791.2 | D49: =VLOOKUP($A49,[1]Data!$B$1:$BK$65536,D$1-1956,FALSE)*VLOOKUP($A49,[2]Data!$B$1:$BK$65536,D$1-1956,FALSE)/100 -> 2238300.4 | E49: =VLOOKUP($A49,[1]Data!$B$1:$BK$65536,E$1-1956,FALSE)*VLOOKUP($A49,[2]Data!$B$1:$BK$65536,E$1-1956,FALSE)/100 -> 2180274.1 | F49: =VLOOKUP($A49,[1]Data!$B$1:$BK$65536,F$1-1956,FALSE)*VLOOKUP($A49,[2]Data!$B$1:$BK$65536,F$1-1956,FALSE)/100 -> 2104585 | G49: =VLOOKUP($A49,[1]Data!$B$1:$BK$65536,G$1-1956,FALSE)*VLOOKUP($A49,[2]Data!$B$1:$BK$65536,G$1-1956,FALSE)/100 -> 2011987 | H49: =VLOOKUP($A49,[1]Data!$B$1:$BK$65536,H$1-1956,FALSE)*VLOOKUP($A49,[2]Data!$B$1:$BK$65536,H$1-1956,FALSE)/100 -> 1928733.5 | I49: =VLOOKUP($A49,[1]Data!$B$1:$BK$65536,I$1-1956,FALSE)*VLOOKUP($A49,[2]Data!$B$1:$BK$65536,I$1-1956,FALSE)/100 -> 1911025.6 | ... U49: =VLOOKUP($A49,[1]Data!$B$1:$BK$65536,U$1-1956,FALSE)*VLOOKUP($A49,[2]Data!$B$1:$BK$65536,U$1-1956,FALSE)/100 -> 1827635.7
A50: NOR | B50: =VLOOKUP($A50,[1]Data!$B$1:$BK$65536,B$1-1956,FALSE)*VLOOKUP($A50,[2]Data!$B$1:$BK$65536,B$1-1956,FALSE)/100 -> 2575231.5 | C50: =VLOOKUP($A50,[1]Data!$B$1:$BK$65536,C$1-1956,FALSE)*VLOOKUP($A50,[2]Data!$B$1:$BK$65536,C$1-1956,FALSE)/100 -> 2677215.3 | D50: =VLOOKUP($A50,[1]Data!$B$1:$BK$65536,D$1-1956,FALSE)*VLOOKUP($A50,[2]Data!$B$1:$BK$65536,D$1-1956,FALSE)/100 -> 2764632.4 | E50: =VLOOKUP($A50,[1]Data!$B$1:$BK$65536,E$1-1956,FALSE)*VLOOKUP($A50,[2]Data!$B$1:$BK$65536,E$1-1956,FALSE)/100 -> 2851514.1 | F50: =VLOOKUP($A50,[1]Data!$B$1:$BK$65536,F$1-1956,FALSE)*VLOOKUP($A50,[2]Data!$B$1:$BK$65536,F$1-1956,FALSE)/100 -> 2875390.6 | G50: =VLOOKUP($A50,[1]Data!$B$1:$BK$65536,G$1-1956,FALSE)*VLOOKUP($A50,[2]Data!$B$1:$BK$65536,G$1-1956,FALSE)/100 -> 2900625.7 | H50: =VLOOKUP($A50,[1]Data!$B$1:$BK$65536,H$1-1956,FALSE)*VLOOKUP($A50,[2]Data!$B$1:$BK$65536,H$1-1956,FALSE)/100 -> 2905366 | I50: =VLOOKUP($A50,[1]Data!$B$1:$BK$65536,I$1-1956,FALSE)*VLOOKUP($A50,[2]Data!$B$1:$BK$65536,I$1-1956,FALSE)/100 -> 2921394.5 | ... U50: =VLOOKUP($A50,[1]Data!$B$1:$BK$65536,U$1-1956,FALSE)*VLOOKUP($A50,[2]Data!$B$1:$BK$65536,U$1-1956,FALSE)/100 -> 3208920.6
A52: SOMA-16 | B52: =SUM(B48:B50)+B44 -> 2.391357e+09 | C52: =SUM(C48:C50)+C44 -> 2.4110603e+09 | D52: =SUM(D48:D50)+D44 -> 2.4338326e+09 | E52: =SUM(E48:E50)+E44 -> 2.4529908e+09 | F52: =SUM(F48:F50)+F44 -> 2.4788666e+09 | G52: =SUM(G48:G50)+G44 -> 2.5006507e+09 | H52: =SUM(H48:H50)+H44 -> 2.5070886e+09 | I52: =SUM(I48:I50)+I44 -> 2.5109118e+09 | ... U52: =SUM(U48:U50)+U44 -> 2.6219289e+09
A53: ROW-16 | B53: =B42-SUM(B2:B41)-SUM(B48:B50) -> 1.121168e+09 | C53: =C42-SUM(C2:C41)-SUM(C48:C50) -> 1.1418063e+09 | D53: =D42-SUM(D2:D41)-SUM(D48:D50) -> 1.1645028e+09 | E53: =E42-SUM(E2:E41)-SUM(E48:E50) -> 1.1828314e+09 | F53: =F42-SUM(F2:F41)-SUM(F48:F50) -> 1.2016211e+09 | G53: =G42-SUM(G2:G41)-SUM(G48:G50) -> 1.2259473e+09 | H53: =H42-SUM(H2:H41)-SUM(H48:H50) -> 1.247804e+09 | I53: =I42-SUM(I2:I41)-SUM(I48:I50) -> 1.2675354e+09 | ... U53: =U42-SUM(U2:U41)-SUM(U48:U50) -> 1.588681e+09
A58: TWN | B58: 1995 | C58: 1996 | D58: 1997 | E58: 1998 | F58: 1999 | G58: 2000 | H58: 2001 | I58: 2002 | J58: 2003 | K58: 2004 | L58: 2005 | M58: 2006 | N58: 2007 | O58: 2008 | P58: 2009 | Q58: 2010 | R58: 2011 | S58: 2012 | T58: 2013 | U58: 2014
A59: População | B59: 21177874 | C59: 21357431 | D59: 21525433 | E59: 21742815 | F59: 21928591 | G59: 22092387 | H59: 22276672 | I59: 22405568 | J59: 22520776 | K59: 22604550 | L59: 22689122 | M59: 22770383 | N59: 22876527 | O59: 22958360 | P59: 23037031 | Q59: 23119772 | R59: 23162123 | S59: 23224912 | T59: 23315822 | U59: 23373517
A60: Emprego | B60: 9068000 | C60: 9176000 | D60: 9289000 | E60: 9385000 | F60: 9491000 | G60: 9383000 | H60: 9454000 | I60: 9573000 | J60: 9786000 | K60: 9942000 | L60: 10111000 | M60: 10294000 | N60: 10403000 | O60: 10279000 | P60: 10493000 | Q60: 10709000 | R60: 10860000 | S60: 10967000 | T60: 11079000 | U60: 11198000

Sheet Emprego - WIOD-14
A1: Country | B1: _1995 | C1: _1996 | D1: _1997 | E1: _1998 | F1: _1999 | G1: _2000 | H1: _2001 | I1: _2002 | J1: _2003 | K1: _2004 | L1: _2005 | M1: _2006 | N1: _2007 | O1: _2008 | P1: _2009 | Q1: _2010 | R1: _2011
A2: AUS | B2: 8288820 | C2: 8354550 | D2: 8476975 | E2: 8641615 | F2: 8833540 | G2: 9012162.4 | H2: 9129560.8 | I2: 9366902.8 | J2: 9518830.4 | K2: 9773745.4 | L2: 10028876 | M2: 10288121 | N2: 10558402 | O2: 10861213 | P2: 10935421 | Q2: 11143300 | R2: 11331552
A3: AUT | B3: 3717450 | C3: 3745607 | D3: 3773250 | E3: 3812808 | F3: 3880567 | G3: 3931132 | H3: 3958982 | I3: 3959496 | J3: 3971206 | K3: 3986006 | L3: 4031292 | M3: 4090488 | N3: 4160866 | O3: 4300196.3 | P3: 4212848.6 | Q3: 4213622.7 | R3: 4294954.4
A4: BEL | B4: 3867180 | C4: 3877602 | D4: 3904154 | E4: 3972758 | F4: 4027605 | G4: 4108957 | H4: 4165431 | I4: 4158946 | J4: 4160432 | K4: 4198741 | L4: 4258009 | M4: 4308495 | N4: 4378108 | O4: 4449893.3 | P4: 4437555.6 | Q4: 4474488.3 | R4: 4530339.2
A5: BGR | B5: 3518768.8 | C5: 3613757.6 | D5: 3500495.2 | E5: 3472496.6 | F5: 3312407.7 | G5: 3239300 | H5: 3214800 | I5: 3222200 | J5: 3317400 | K5: 3403500 | L5: 3495200 | M5: 3612000 | N5: 3726600 | O5: 3759606.5 | P5: 3739755.2 | Q5: 3612515 | R5: 3462971.9
A6: BRA | B6: 73545222 | C6: 71985645 | D6: 73128236 | E6: 72744861 | F6: 76641008 | G6: 78972347 | H6: 79544414 | I6: 82629067 | J6: 84034981 | K6: 88252473 | L6: 90905673 | M6: 93246963 | N6: 94713909 | O6: 96232609 | P6: 96647139 | Q6: 1.0189057e+08 | R6: 1.0583315e+08
A7: CAN | B7: 13593007 | C7: 13739222 | D7: 14027670 | E7: 14345415 | F7: 14719775 | G7: 15048150 | H7: 15199155 | I7: 15568200 | J7: 15901975 | K7: 16165970 | L7: 16405415 | M7: 16676750 | N7: 17046850 | O7: 17485671 | P7: 16875447 | Q7: 17290192 | R7: 17586451
A8: CHN | B8: 680650000 | C8: 689500000 | D8: 698200000 | E8: 706370000 | F8: 713940000 | G8: 720850000 | H8: 730250000 | I8: 737400000 | J8: 744320000 | K8: 752000000 | L8: 758250000 | M8: 764000000 | N8: 769900000 | O8: 774800000 | P8: 779950000 | Q8: 7.9934753e+08 | R8: 8.0856477e+08
A9: CYP | B9: 296100 | C9: 297700 | D9: 299500 | E9: 304100 | F9: 309800 | G9: 314800 | H9: 321900 | I9: 328300 | J9: 340800 | K9: 353300 | L9: 366400 | M9: 372400 | N9: 384500 | O9: 391166.67 | P9: 392612.73 | Q9: 397161.01 | R9: 394301.07
A10: CZE | B10: 5148229 | C10: 5195164 | D10: 5204858 | E10: 5124530 | F10: 4949350 | G10: 4940463 | H10: 4962963 | I10: 4990747 | J10: 4923446 | K10: 4940371 | L10: 4991618 | M10: 5088340 | N10: 5223840 | O10: 5348855.4 | P10: 5231900.7 | Q10: 5163679.6 | R10: 5147377.5
A11: DEU | B11: 37601000 | C11: 37498000 | D11: 37463000 | E11: 37911000 | F11: 38424000 | G11: 39144000 | H11: 39316000 | I11: 39096000 | J11: 38726000 | K11: 38880000 | L11: 38835000 | M11: 39075000 | N11: 39724000 | O11: 40450358 | P11: 40849767 | Q11: 41125172 | R11: 41986635
A12: DNK | B12: 2552724 | C12: 2584116 | D12: 2627783 | E12: 2668106 | F12: 2693717 | G12: 2712496 | H12: 2742475 | I12: 2745960 | J12: 2713539 | K12: 2697642 | L12: 2726912 | M12: 2783454 | N12: 2860799 | O12: 2907479.8 | P12: 2856442.1 | Q12: 2750837.9 | R12: 2738803.6
A13: ESP | B13: 13569301 | C13: 13795999 | D13: 14293301 | E13: 14932000 | F13: 15617099 | G13: 16411500 | H13: 16930600 | I13: 17337600 | J13: 17877600 | K13: 18509800 | L13: 19267300 | M13: 20022000 | N13: 20628500 | O13: 20576317 | P13: 19257726 | Q13: 18690011 | R13: 18247179
... A41: USA | B41: 1.3397932e+08 | C41: 1.3602293e+08 | D41: 1.3854783e+08 | E41: 1.4188742e+08 | F41: 1.4453441e+08 | G41: 1.4771668e+08 | H41: 1.4681783e+08 | I41: 1.4539904e+08 | J41: 1.4518904e+08 | K41: 1.46865e+08 | L41: 1.4890333e+08 | M41: 1.5131939e+08 | N41: 1.5256715e+08 | O41: 1.5174279e+08 | P41: 1.4534483e+08 | Q41: 1.4454039e+08 | R41: 1.4554849e+08
A43: Total | B43: =SUM(B2:B41) -> 1.8042469e+09 | C43: =SUM(C2:C41) -> 1.8294535e+09 | D43: =SUM(D2:D41) -> 1.8512181e+09 | E43: =SUM(E2:E41) -> 1.8677215e+09 | F43: =SUM(F2:F41) -> 1.8878127e+09 | G43: =SUM(G2:G41) -> 1.9259849e+09 | H43: =SUM(H2:H41) -> 1.9539633e+09 | I43: =SUM(I2:I41) -> 1.9557498e+09 | ... R43: =SUM(R2:R41) -> 2.1578842e+09

Sheet Emprego - WIOD-16
B1: 2000 | C1: 2001 | D1: 2002 | E1: 2003 | F1: 2004 | G1: 2005 | H1: 2006 | I1: 2007 | J1: 2008 | K1: 2009 | L1: 2010 | M1: 2011 | N1: 2012 | O1: 2013 | P1: 2014
A2: AUS | B2: 9044700 | C2: 9182650 | D2: 9430010 | E2: 9581592 | F2: 9903713 | G2: 10145585 | H2: 10466510 | I2: 10752408 | J2: 10865505 | K2: 11024775 | L2: 11271706 | M2: 11472686 | N2: 11557676 | O2: 11621580 | P2: 11863007
A3: AUT | B3: 3756460 | C3: 3783490 | D3: 3779940 | E3: 3804560 | F3: 3828330 | G3: 3873820 | H3: 3941430 | I3: 4013690 | J3: 4090350 | K3: 4072620 | L3: 4102240 | M3: 4166000 | N3: 4211030 | O3: 4230600 | P3: 4268490
A4: BEL | B4: 4108800 | C4: 4165200 | D4: 4157500 | E4: 4154000 | F4: 4194500 | G4: 4255500 | H4: 4302900 | I4: 4373900 | J4: 4453300 | K4: 4445500 | L4: 4474000 | M4: 4535800 | N4: 4551500 | O4: 4534100 | P4: 4549800
A5: BGR | B5: 3319350 | C5: 3309510 | D5: 3312160 | E5: 3402680 | F5: 3484980 | G5: 3564530 | H5: 3702580 | I5: 3823620 | J5: 3915630 | K5: 3859510 | L5: 3680590 | M5: 3585490 | N5: 3474040 | O5: 3470070 | P5: 3600340
A6: BRA | B6: 81003280 | C6: 81869941 | D6: 85428531 | E6: 86351144 | F6: 90883574 | G6: 94080942 | H6: 95555438 | I6: 97563631 | J6: 99373771 | K6: 99517771 | L6: 99173384 | M6: 1.0026057e+08 | N6: 1.0149193e+08 | O6: 1.0299307e+08 | P6: 1.0403146e+08
A7: CAN | B7: 15143131 | C7: 15302796 | D7: 15686348 | E7: 16036946 | F7: 16287254 | G7: 16534560 | H7: 16814489 | I7: 17223936 | J7: 17704097 | K7: 16889310 | L7: 17210866 | M7: 17377209 | N7: 17555443 | O7: 17772837 | P7: 18449875
A8: CHE | B8: 4012254 | C8: 4118131 | D8: 4146218 | E8: 4134238 | F8: 4165458 | G8: 4204780 | H8: 4285666 | I8: 4398199 | J8: 4501677 | K8: 4580104 | L8: 4683310 | M8: 4890381 | N8: 4960441 | O8: 5021571 | P8: 5084671
A9: CHN | B9: 719604312 | C9: 7.2810745e+08 | D9: 737283544 | E9: 7.4453105e+08 | F9: 7.5228098e+08 | G9: 7.5976971e+08 | H9: 7.6535319e+08 | I9: 770887157 | J9: 777013044 | K9: 7.8492394e+08 | L9: 7.8466254e+08 | M9: 8.4044302e+08 | N9: 8.5421628e+08 | O9: 857825563 | P9: 858367350
A10: CYP | B10: 316400 | C10: 323510 | D10: 330460 | E10: 342550 | F10: 356140 | G10: 368510 | H10: 375380 | I10: 388690 | J10: 396310 | K10: 394460 | L10: 401280 | M10: 403460 | N10: 388970 | O10: 365010 | P10: 357510
A11: CZE | B11: 4859390 | C11: 4846400 | D11: 4876770 | E11: 4838090 | F11: 4828910 | G11: 4922670 | H11: 4988980 | I11: 5093160 | J11: 5204090 | K11: 5110140 | L11: 5057260 | M11: 5043460 | N11: 5064670 | O11: 5081060 | P11: 5109230
A12: DEU | B12: 39917000 | C12: 39809000 | D12: 39630000 | E12: 39200000 | F12: 39337000 | G12: 39326000 | H12: 39635000 | I12: 40325000 | J12: 40856000 | K12: 40892000 | L12: 41020000 | M12: 41577000 | N12: 42060000 | O12: 42328000 | P12: 42706000
A13: DNK | B13: 2736000 | C13: 2754000 | D13: 2754000 | E13: 2735000 | F13: 2712000 | G13: 2756000 | H13: 2816000 | I13: 2877000 | J13: 2911000 | K13: 2825000 | L13: 2759000 | M13: 2757000 | N13: 2741000 | O13: 2745000 | P13: 2765000
... A44: USA | B44: 1.5043335e+08 | C44: 150399160 | D44: 1.4919215e+08 | E44: 1.4858927e+08 | F44: 1.5004819e+08 | G44: 1.5199962e+08 | H44: 1.5500865e+08 | I44: 1.555685e+08 | J44: 1.5469618e+08 | K44: 1.4790628e+08 | L44: 146533434 | M44: 1.4789864e+08 | N44: 1.5063103e+08 | O44: 1.5295808e+08 | P44: 1.5577046e+08
A46: Total | B46: =SUM(B2:B44) -> 1.9329204e+09 | C46: =SUM(C2:C44) -> 1.9578879e+09 | D46: =SUM(D2:D44) -> 1.9823835e+09 | E46: =SUM(E2:E44) -> 2.0095397e+09 | F46: =SUM(F2:F44) -> 2.0429359e+09 | G46: =SUM(G2:G44) -> 2.0641803e+09 | H46: =SUM(H2:H44) -> 2.0826754e+09 | I46: =SUM(I2:I44) -> 2.1029402e+09 | ... P46: =SUM(P2:P44) -> 2.4622818e+09

Sheet Dif WIOD-14 e 16
B1: 2000 | C1: 2001 | D1: 2002 | E1: 2003 | F1: 2004 | G1: 2005 | H1: 2006 | I1: 2007 | J1: 2008 | K1: 2009 | L1: 2010 | M1: 2011
A2: AUS | B2: =(VLOOKUP($A2,'Emprego - WIOD-14'!$A:$R,B$1-1993,FALSE)-VLOOKUP($A2,'Emprego - WIOD-16'!$A:$R,B$1-1998,FALSE))/VLOOKUP($A2,'Emprego - WIOD-14'!$A:$R,B$1-1993,FALSE) -> -0.0036104129 | C2: =(VLOOKUP($A2,'Emprego - WIOD-14'!$A:$R,C$1-1993,FALSE)-VLOOKUP($A2,'Emprego - WIOD-16'!$A:$R,C$1-1998,FALSE))/VLOOKUP($A2,'Emprego - WIOD-14'!$A:$R,C$1-1993,FALSE) -> -0.0058150873 | D2: =(VLOOKUP($A2,'Emprego - WIOD-14'!$A:$R,D$1-1993,FALSE)-VLOOKUP($A2,'Emprego - WIOD-16'!$A:$R,D$1-1998,FALSE))/VLOOKUP($A2,'Emprego - WIOD-14'!$A:$R,D$1-1993,FALSE) -> -0.0067372484 | E2: =(VLOOKUP($A2,'Emprego - WIOD-14'!$A:$R,E$1-1993,FALSE)-VLOOKUP($A2,'Emprego - WIOD-16'!$A:$R,E$1-1998,FALSE))/VLOOKUP($A2,'Emprego - WIOD-14'!$A:$R,E$1-1993,FALSE) -> -0.0065934142 | F2: =(VLOOKUP($A2,'Emprego - WIOD-14'!$A:$R,F$1-1993,FALSE)-VLOOKUP($A2,'Emprego - WIOD-16'!$A:$R,F$1-1998,FALSE))/VLOOKUP($A2,'Emprego - WIOD-14'!$A:$R,F$1-1993,FALSE) -> -0.013297624 | G2: =(VLOOKUP($A2,'Emprego - WIOD-14'!$A:$R,G$1-1993,FALSE)-VLOOKUP($A2,'Emprego - WIOD-16'!$A:$R,G$1-1998,FALSE))/VLOOKUP($A2,'Emprego - WIOD-14'!$A:$R,G$1-1993,FALSE) -> -0.01163731 | H2: =(VLOOKUP($A2,'Emprego - WIOD-14'!$A:$R,H$1-1993,FALSE)-VLOOKUP($A2,'Emprego - WIOD-16'!$A:$R,H$1-1998,FALSE))/VLOOKUP($A2,'Emprego - WIOD-14'!$A:$R,H$1-1993,FALSE) -> -0.01733931 | I2: =(VLOOKUP($A2,'Emprego - WIOD-14'!$A:$R,I$1-1993,FALSE)-VLOOKUP($A2,'Emprego - WIOD-16'!$A:$R,I$1-1998,FALSE))/VLOOKUP($A2,'Emprego - WIOD-14'!$A:$R,I$1-1993,FALSE) -> -0.018374556 | ... M2: =(VLOOKUP($A2,'Emprego - WIOD-14'!$A:$R,M$1-1993,FALSE)-VLOOKUP($A2,'Emprego - WIOD-16'!$A:$R,M$1-1998,FALSE))/VLOOKUP($A2,'Emprego - WIOD-14'!$A:$R,M$1-1993,FALSE) -> -0.012454943
A3: AUT | B3: =(VLOOKUP($A3,'Emprego - WIOD-14'!$A:$R,B$1-1993,FALSE)-VLOOKUP($A3,'Emprego - WIOD-16'!$A:$R,B$1-1998,FALSE))/VLOOKUP($A3,'Emprego - WIOD-14'!$A:$R,B$1-1993,FALSE) -> 0.044433003 | C3: =(VLOOKUP($A3,'Emprego - WIOD-14'!$A:$R,C$1-1993,FALSE)-VLOOKUP($A3,'Emprego - WIOD-16'!$A:$R,C$1-1998,FALSE))/VLOOKUP($A3,'Emprego - WIOD-14'!$A:$R,C$1-1993,FALSE) -> 0.044327557 | D3: =(VLOOKUP($A3,'Emprego - WIOD-14'!$A:$R,D$1-1993,FALSE)-VLOOKUP($A3,'Emprego - WIOD-16'!$A:$R,D$1-1998,FALSE))/VLOOKUP($A3,'Emprego - WIOD-14'!$A:$R,D$1-1993,FALSE) -> 0.045348196 | E3: =(VLOOKUP($A3,'Emprego - WIOD-14'!$A:$R,E$1-1993,FALSE)-VLOOKUP($A3,'Emprego - WIOD-16'!$A:$R,E$1-1998,FALSE))/VLOOKUP($A3,'Emprego - WIOD-14'!$A:$R,E$1-1993,FALSE) -> 0.041963575 | F3: =(VLOOKUP($A3,'Emprego - WIOD-14'!$A:$R,F$1-1993,FALSE)-VLOOKUP($A3,'Emprego - WIOD-16'!$A:$R,F$1-1998,FALSE))/VLOOKUP($A3,'Emprego - WIOD-14'!$A:$R,F$1-1993,FALSE) -> 0.039557392 | G3: =(VLOOKUP($A3,'Emprego - WIOD-14'!$A:$R,G$1-1993,FALSE)-VLOOKUP($A3,'Emprego - WIOD-16'!$A:$R,G$1-1998,FALSE))/VLOOKUP($A3,'Emprego - WIOD-14'!$A:$R,G$1-1993,FALSE) -> 0.039062415 | H3: =(VLOOKUP($A3,'Emprego - WIOD-14'!$A:$R,H$1-1993,FALSE)-VLOOKUP($A3,'Emprego - WIOD-16'!$A:$R,H$1-1998,FALSE))/VLOOKUP($A3,'Emprego - WIOD-14'!$A:$R,H$1-1993,FALSE) -> 0.036440151 | I3: =(VLOOKUP($A3,'Emprego - WIOD-14'!$A:$R,I$1-1993,FALSE)-VLOOKUP($A3,'Emprego - WIOD-16'!$A:$R,I$1-1998,FALSE))/VLOOKUP($A3,'Emprego - WIOD-14'!$A:$R,I$1-1993,FALSE) -> 0.035371483 | ... M3: =(VLOOKUP($A3,'Emprego - WIOD-14'!$A:$R,M$1-1993,FALSE)-VLOOKUP($A3,'Emprego - WIOD-16'!$A:$R,M$1-1998,FALSE))/VLOOKUP($A3,'Emprego - WIOD-14'!$A:$R,M$1-1993,FALSE) -> 0.030024631
A4: BEL | B4: =(VLOOKUP($A4,'Emprego - WIOD-14'!$A:$R,B$1-1993,FALSE)-VLOOKUP($A4,'Emprego - WIOD-16'!$A:$R,B$1-1998,FALSE))/VLOOKUP($A4,'Emprego - WIOD-14'!$A:$R,B$1-1993,FALSE) -> 3.820921e-05 | C4: =(VLOOKUP($A4,'Emprego - WIOD-14'!$A:$R,C$1-1993,FALSE)-VLOOKUP($A4,'Emprego - WIOD-16'!$A:$R,C$1-1998,FALSE))/VLOOKUP($A4,'Emprego - WIOD-14'!$A:$R,C$1-1993,FALSE) -> 5.5456446e-05 | D4: =(VLOOKUP($A4,'Emprego - WIOD-14'!$A:$R,D$1-1993,FALSE)-VLOOKUP($A4,'Emprego - WIOD-16'!$A:$R,D$1-1998,FALSE))/VLOOKUP($A4,'Emprego - WIOD-14'!$A:$R,D$1-1993,FALSE) -> 0.00034768424 | E4: =(VLOOKUP($A4,'Emprego - WIOD-14'!$A:$R,E$1-1993,FALSE)-VLOOKUP($A4,'Emprego - WIOD-16'!$A:$R,E$1-1998,FALSE))/VLOOKUP($A4,'Emprego - WIOD-14'!$A:$R,E$1-1993,FALSE) -> 0.0015459933 | F4: =(VLOOKUP($A4,'Emprego - WIOD-14'!$A:$R,F$1-1993,FALSE)-VLOOKUP($A4,'Emprego - WIOD-16'!$A:$R,F$1-1998,FALSE))/VLOOKUP($A4,'Emprego - WIOD-14'!$A:$R,F$1-1993,FALSE) -> 0.0010100647 | G4: =(VLOOKUP($A4,'Emprego - WIOD-14'!$A:$R,G$1-1993,FALSE)-VLOOKUP($A4,'Emprego - WIOD-16'!$A:$R,G$1-1998,FALSE))/VLOOKUP($A4,'Emprego - WIOD-14'!$A:$R,G$1-1993,FALSE) -> 0.00058924253 | H4: =(VLOOKUP($A4,'Emprego - WIOD-14'!$A:$R,H$1-1993,FALSE)-VLOOKUP($A4,'Emprego - WIOD-16'!$A:$R,H$1-1998,FALSE))/VLOOKUP($A4,'Emprego - WIOD-14'!$A:$R,H$1-1993,FALSE) -> 0.0012985973 | I4: =(VLOOKUP($A4,'Emprego - WIOD-14'!$A:$R,I$1-1993,FALSE)-VLOOKUP($A4,'Emprego - WIOD-16'!$A:$R,I$1-1998,FALSE))/VLOOKUP($A4,'Emprego - WIOD-14'!$A:$R,I$1-1993,FALSE) -> 0.00096114577 | ... M4: =(VLOOKUP($A4,'Emprego - WIOD-14'!$A:$R,M$1-1993,FALSE)-VLOOKUP($A4,'Emprego - WIOD-16'!$A:$R,M$1-1998,FALSE))/VLOOKUP($A4,'Emprego - WIOD-14'!$A:$R,M$1-1993,FALSE) -> -0.00120538
A5: BGR | B5: =(VLOOKUP($A5,'Emprego - WIOD-14'!$A:$R,B$1-1993,FALSE)-VLOOKUP($A5,'Emprego - WIOD-16'!$A:$R,B$1-1998,FALSE))/VLOOKUP($A5,'Emprego - WIOD-14'!$A:$R,B$1-1993,FALSE) -> -0.024712129 | C5: =(VLOOKUP($A5,'Emprego - WIOD-14'!$A:$R,C$1-1993,FALSE)-VLOOKUP($A5,'Emprego - WIOD-16'!$A:$R,C$1-1998,FALSE))/VLOOKUP($A5,'Emprego - WIOD-14'!$A:$R,C$1-1993,FALSE) -> -0.02946062 | D5: =(VLOOKUP($A5,'Emprego - WIOD-14'!$A:$R,D$1-1993,FALSE)-VLOOKUP($A5,'Emprego - WIOD-16'!$A:$R,D$1-1998,FALSE))/VLOOKUP($A5,'Emprego - WIOD-14'!$A:$R,D$1-1993,FALSE) -> -0.027918813 | E5: =(VLOOKUP($A5,'Emprego - WIOD-14'!$A:$R,E$1-1993,FALSE)-VLOOKUP($A5,'Emprego - WIOD-16'!$A:$R,E$1-1998,FALSE))/VLOOKUP($A5,'Emprego - WIOD-14'!$A:$R,E$1-1993,FALSE) -> -0.025706879 | F5: =(VLOOKUP($A5,'Emprego - WIOD-14'!$A:$R,F$1-1993,FALSE)-VLOOKUP($A5,'Emprego - WIOD-16'!$A:$R,F$1-1998,FALSE))/VLOOKUP($A5,'Emprego - WIOD-14'!$A:$R,F$1-1993,FALSE) -> -0.023940062 | G5: =(VLOOKUP($A5,'Emprego - WIOD-14'!$A:$R,G$1-1993,FALSE)-VLOOKUP($A5,'Emprego - WIOD-16'!$A:$R,G$1-1998,FALSE))/VLOOKUP($A5,'Emprego - WIOD-14'!$A:$R,G$1-1993,FALSE) -> -0.019835775 | H5: =(VLOOKUP($A5,'Emprego - WIOD-14'!$A:$R,H$1-1993,FALSE)-VLOOKUP($A5,'Emprego - WIOD-16'!$A:$R,H$1-1998,FALSE))/VLOOKUP($A5,'Emprego - WIOD-14'!$A:$R,H$1-1993,FALSE) -> -0.025077519 | I5: =(VLOOKUP($A5,'Emprego - WIOD-14'!$A:$R,I$1-1993,FALSE)-VLOOKUP($A5,'Emprego - WIOD-16'!$A:$R,I$1-1998,FALSE))/VLOOKUP($A5,'Emprego - WIOD-14'!$A:$R,I$1-1993,FALSE) -> -0.026034455 | ... M5: =(VLOOKUP($A5,'Emprego - WIOD-14'!$A:$R,M$1-1993,FALSE)-VLOOKUP($A5,'Emprego - WIOD-16'!$A:$R,M$1-1998,FALSE))/VLOOKUP($A5,'Emprego - WIOD-14'!$A:$R,M$1-1993,FALSE) -> -0.035379472
A6: BRA | B6: =(VLOOKUP($A6,'Emprego - WIOD-14'!$A:$R,B$1-1993,FALSE)-VLOOKUP($A6,'Emprego - WIOD-16'!$A:$R,B$1-1998,FALSE))/VLOOKUP($A6,'Emprego - WIOD-14'!$A:$R,B$1-1993,FALSE) -> -0.025717015 | C6: =(VLOOKUP($A6,'Emprego - WIOD-14'!$A:$R,C$1-1993,FALSE)-VLOOKUP($A6,'Emprego - WIOD-16'!$A:$R,C$1-1998,FALSE))/VLOOKUP($A6,'Emprego - WIOD-14'!$A:$R,C$1-1993,FALSE) -> -0.029235579 | D6: =(VLOOKUP($A6,'Emprego - WIOD-14'!$A:$R,D$1-1993,FALSE)-VLOOKUP($A6,'Emprego - WIOD-16'!$A:$R,D$1-1998,FALSE))/VLOOKUP($A6,'Emprego - WIOD-14'!$A:$R,D$1-1993,FALSE) -> -0.033879894 | E6: =(VLOOKUP($A6,'Emprego - WIOD-14'!$A:$R,E$1-1993,FALSE)-VLOOKUP($A6,'Emprego - WIOD-16'!$A:$R,E$1-1998,FALSE))/VLOOKUP($A6,'Emprego - WIOD-14'!$A:$R,E$1-1993,FALSE) -> -0.027561891 | F6: =(VLOOKUP($A6,'Emprego - WIOD-14'!$A:$R,F$1-1993,FALSE)-VLOOKUP($A6,'Emprego - WIOD-16'!$A:$R,F$1-1998,FALSE))/VLOOKUP($A6,'Emprego - WIOD-14'!$A:$R,F$1-1993,FALSE) -> -0.02981334 | G6: =(VLOOKUP($A6,'Emprego - WIOD-14'!$A:$R,G$1-1993,FALSE)-VLOOKUP($A6,'Emprego - WIOD-16'!$A:$R,G$1-1998,FALSE))/VLOOKUP($A6,'Emprego - WIOD-14'!$A:$R,G$1-1993,FALSE) -> -0.034929272 | H6: =(VLOOKUP($A6,'Emprego - WIOD-14'!$A:$R,H$1-1993,FALSE)-VLOOKUP($A6,'Emprego - WIOD-16'!$A:$R,H$1-1998,FALSE))/VLOOKUP($A6,'Emprego - WIOD-14'!$A:$R,H$1-1993,FALSE) -> -0.02475657 | I6: =(VLOOKUP($A6,'Emprego - WIOD-14'!$A:$R,I$1-1993,FALSE)-VLOOKUP($A6,'Emprego - WIOD-16'!$A:$R,I$1-1998,FALSE))/VLOOKUP($A6,'Emprego - WIOD-14'!$A:$R,I$1-1993,FALSE) -> -0.030087682 | ... M6: =(VLOOKUP($A6,'Emprego - WIOD-14'!$A:$R,M$1-1993,FALSE)-VLOOKUP($A6,'Emprego - WIOD-16'!$A:$R,M$1-1998,FALSE))/VLOOKUP($A6,'Emprego - WIOD-14'!$A:$R,M$1-1993,FALSE) -> 0.052654392
A7: CAN | B7: =(VLOOKUP($A7,'Emprego - WIOD-14'!$A:$R,B$1-1993,FALSE)-VLOOKUP($A7,'Emprego - WIOD-16'!$A:$R,B$1-1998,FALSE))/VLOOKUP($A7,'Emprego - WIOD-14'!$A:$R,B$1-1993,FALSE) -> -0.0063118059 | C7: =(VLOOKUP($A7,'Emprego - WIOD-14'!$A:$R,C$1-1993,FALSE)-VLOOKUP($A7,'Emprego - WIOD-16'!$A:$R,C$1-1998,FALSE))/VLOOKUP($A7,'Emprego - WIOD-14'!$A:$R,C$1-1993,FALSE) -> -0.006818866 | D7: =(VLOOKUP($A7,'Emprego - WIOD-14'!$A:$R,D$1-1993,FALSE)-VLOOKUP($A7,'Emprego - WIOD-16'!$A:$R,D$1-1998,FALSE))/VLOOKUP($A7,'Emprego - WIOD-14'!$A:$R,D$1-1993,FALSE) -> -0.0075890599 | E7: =(VLOOKUP($A7,'Emprego - WIOD-14'!$A:$R,E$1-1993,FALSE)-VLOOKUP($A7,'Emprego - WIOD-16'!$A:$R,E$1-1998,FALSE))/VLOOKUP($A7,'Emprego - WIOD-14'!$A:$R,E$1-1993,FALSE) -> -0.008487688 | F7: =(VLOOKUP($A7,'Emprego - WIOD-14'!$A:$R,F$1-1993,FALSE)-VLOOKUP($A7,'Emprego - WIOD-16'!$A:$R,F$1-1998,FALSE))/VLOOKUP($A7,'Emprego - WIOD-14'!$A:$R,F$1-1993,FALSE) -> -0.0075024265 | G7: =(VLOOKUP($A7,'Emprego - WIOD-14'!$A:$R,G$1-1993,FALSE)-VLOOKUP($A7,'Emprego - WIOD-16'!$A:$R,G$1-1998,FALSE))/VLOOKUP($A7,'Emprego - WIOD-14'!$A:$R,G$1-1993,FALSE) -> -0.007872096 | H7: =(VLOOKUP($A7,'Emprego - WIOD-14'!$A:$R,H$1-1993,FALSE)-VLOOKUP($A7,'Emprego - WIOD-16'!$A:$R,H$1-1998,FALSE))/VLOOKUP($A7,'Emprego - WIOD-14'!$A:$R,H$1-1993,FALSE) -> -0.0082593432 | I7: =(VLOOKUP($A7,'Emprego - WIOD-14'!$A:$R,I$1-1993,FALSE)-VLOOKUP($A7,'Emprego - WIOD-16'!$A:$R,I$1-1998,FALSE))/VLOOKUP($A7,'Emprego - WIOD-14'!$A:$R,I$1-1993,FALSE) -> -0.010388195 | ... M7: =(VLOOKUP($A7,'Emprego - WIOD-14'!$A:$R,M$1-1993,FALSE)-VLOOKUP($A7,'Emprego - WIOD-16'!$A:$R,M$1-1998,FALSE))/VLOOKUP($A7,'Emprego - WIOD-14'!$A:$R,M$1-1993,FALSE) -> 0.011897889
A8: CHN | B8: =(VLOOKUP($A8,'Emprego - WIOD-14'!$A:$R,B$1-1993,FALSE)-VLOOKUP($A8,'Emprego - WIOD-16'!$A:$R,B$1-1998,FALSE))/VLOOKUP($A8,'Emprego - WIOD-14'!$A:$R,B$1-1993,FALSE) -> 0.0017280821 | C8: =(VLOOKUP($A8,'Emprego - WIOD-14'!$A:$R,C$1-1993,FALSE)-VLOOKUP($A8,'Emprego - WIOD-16'!$A:$R,C$1-1998,FALSE))/VLOOKUP($A8,'Emprego - WIOD-14'!$A:$R,C$1-1993,FALSE) -> 0.0029339897 | D8: =(VLOOKUP($A8,'Emprego - WIOD-14'!$A:$R,D$1-1993,FALSE)-VLOOKUP($A8,'Emprego - WIOD-16'!$A:$R,D$1-1998,FALSE))/VLOOKUP($A8,'Emprego - WIOD-14'!$A:$R,D$1-1993,FALSE) -> 0.00015792785 | E8: =(VLOOKUP($A8,'Emprego - WIOD-14'!$A:$R,E$1-1993,FALSE)-VLOOKUP($A8,'Emprego - WIOD-16'!$A:$R,E$1-1998,FALSE))/VLOOKUP($A8,'Emprego - WIOD-14'!$A:$R,E$1-1993,FALSE) -> -0.00028355412 | F8: =(VLOOKUP($A8,'Emprego - WIOD-14'!$A:$R,F$1-1993,FALSE)-VLOOKUP($A8,'Emprego - WIOD-16'!$A:$R,F$1-1998,FALSE))/VLOOKUP($A8,'Emprego - WIOD-14'!$A:$R,F$1-1993,FALSE) -> -0.00037364096 | G8: =(VLOOKUP($A8,'Emprego - WIOD-14'!$A:$R,G$1-1993,FALSE)-VLOOKUP($A8,'Emprego - WIOD-16'!$A:$R,G$1-1998,FALSE))/VLOOKUP($A8,'Emprego - WIOD-14'!$A:$R,G$1-1993,FALSE) -> -0.0020042282 | H8: =(VLOOKUP($A8,'Emprego - WIOD-14'!$A:$R,H$1-1993,FALSE)-VLOOKUP($A8,'Emprego - WIOD-16'!$A:$R,H$1-1998,FALSE))/VLOOKUP($A8,'Emprego - WIOD-14'!$A:$R,H$1-1993,FALSE) -> -0.0017711937 | I8: =(VLOOKUP($A8,'Emprego - WIOD-14'!$A:$R,I$1-1993,FALSE)-VLOOKUP($A8,'Emprego - WIOD-16'!$A:$R,I$1-1998,FALSE))/VLOOKUP($A8,'Emprego - WIOD-14'!$A:$R,I$1-1993,FALSE) -> -0.0012821886 | ... M8: =(VLOOKUP($A8,'Emprego - WIOD-14'!$A:$R,M$1-1993,FALSE)-VLOOKUP($A8,'Emprego - WIOD-16'!$A:$R,M$1-1998,FALSE))/VLOOKUP($A8,'Emprego - WIOD-14'!$A:$R,M$1-1993,FALSE) -> -0.03942572
A9: CYP | B9: =(VLOOKUP($A9,'Emprego - WIOD-14'!$A:$R,B$1-1993,FALSE)-VLOOKUP($A9,'Emprego - WIOD-16'!$A:$R,B$1-1998,FALSE))/VLOOKUP($A9,'Emprego - WIOD-14'!$A:$R,B$1-1993,FALSE) -> -0.0050825921 | C9: =(VLOOKUP($A9,'Emprego - WIOD-14'!$A:$R,C$1-1993,FALSE)-VLOOKUP($A9,'Emprego - WIOD-16'!$A:$R,C$1-1998,FALSE))/VLOOKUP($A9,'Emprego - WIOD-14'!$A:$R,C$1-1993,FALSE) -> -0.0050015533 | D9: =(VLOOKUP($A9,'Emprego - WIOD-14'!$A:$R,D$1-1993,FALSE)-VLOOKUP($A9,'Emprego - WIOD-16'!$A:$R,D$1-1998,FALSE))/VLOOKUP($A9,'Emprego - WIOD-14'!$A:$R,D$1-1993,FALSE) -> -0.0065793482 | E9: =(VLOOKUP($A9,'Emprego - WIOD-14'!$A:$R,E$1-1993,FALSE)-VLOOKUP($A9,'Emprego - WIOD-16'!$A:$R,E$1-1998,FALSE))/VLOOKUP($A9,'Emprego - WIOD-14'!$A:$R,E$1-1993,FALSE) -> -0.0051349765 | F9: =(VLOOKUP($A9,'Emprego - WIOD-14'!$A:$R,F$1-1993,FALSE)-VLOOKUP($A9,'Emprego - WIOD-16'!$A:$R,F$1-1998,FALSE))/VLOOKUP($A9,'Emprego - WIOD-14'!$A:$R,F$1-1993,FALSE) -> -0.0080384942 | G9: =(VLOOKUP($A9,'Emprego - WIOD-14'!$A:$R,G$1-1993,FALSE)-VLOOKUP($A9,'Emprego - WIOD-16'!$A:$R,G$1-1998,FALSE))/VLOOKUP($A9,'Emprego - WIOD-14'!$A:$R,G$1-1993,FALSE) -> -0.0057587336 | H9: =(VLOOKUP($A9,'Emprego - WIOD-14'!$A:$R,H$1-1993,FALSE)-VLOOKUP($A9,'Emprego - WIOD-16'!$A:$R,H$1-1998,FALSE))/VLOOKUP($A9,'Emprego - WIOD-14'!$A:$R,H$1-1993,FALSE) -> -0.0080021482 | I9: =(VLOOKUP($A9,'Emprego - WIOD-14'!$A:$R,I$1-1993,FALSE)-VLOOKUP($A9,'Emprego - WIOD-16'!$A:$R,I$1-1998,FALSE))/VLOOKUP($A9,'Emprego - WIOD-14'!$A:$R,I$1-1993,FALSE) -> -0.010897269 | ... M9: =(VLOOKUP($A9,'Emprego - WIOD-14'!$A:$R,M$1-1993,FALSE)-VLOOKUP($A9,'Emprego - WIOD-16'!$A:$R,M$1-1998,FALSE))/VLOOKUP($A9,'Emprego - WIOD-14'!$A:$R,M$1-1993,FALSE) -> -0.023228272
A10: CZE | B10: =(VLOOKUP($A10,'Emprego - WIOD-14'!$A:$R,B$1-1993,FALSE)-VLOOKUP($A10,'Emprego - WIOD-16'!$A:$R,B$1-1998,FALSE))/VLOOKUP($A10,'Emprego - WIOD-14'!$A:$R,B$1-1993,FALSE) -> 0.01641 | C10: =(VLOOKUP($A10,'Emprego - WIOD-14'!$A:$R,C$1-1993,FALSE)-VLOOKUP($A10,'Emprego - WIOD-16'!$A:$R,C$1-1998,FALSE))/VLOOKUP($A10,'Emprego - WIOD-14'!$A:$R,C$1-1993,FALSE) -> 0.023486574 | D10: =(VLOOKUP($A10,'Emprego - WIOD-14'!$A:$R,D$1-1993,FALSE)-VLOOKUP($A10,'Emprego - WIOD-16'!$A:$R,D$1-1998,FALSE))/VLOOKUP($A10,'Emprego - WIOD-14'!$A:$R,D$1-1993,FALSE) -> 0.022837663 | E10: =(VLOOKUP($A10,'Emprego - WIOD-14'!$A:$R,E$1-1993,FALSE)-VLOOKUP($A10,'Emprego - WIOD-16'!$A:$R,E$1-1998,FALSE))/VLOOKUP($A10,'Emprego - WIOD-14'!$A:$R,E$1-1993,FALSE) -> 0.017336638 | F10: =(VLOOKUP($A10,'Emprego - WIOD-14'!$A:$R,F$1-1993,FALSE)-VLOOKUP($A10,'Emprego - WIOD-16'!$A:$R,F$1-1998,FALSE))/VLOOKUP($A10,'Emprego - WIOD-14'!$A:$R,F$1-1993,FALSE) -> 0.022561261 | G10: =(VLOOKUP($A10,'Emprego - WIOD-14'!$A:$R,G$1-1993,FALSE)-VLOOKUP($A10,'Emprego - WIOD-16'!$A:$R,G$1-1998,FALSE))/VLOOKUP($A10,'Emprego - WIOD-14'!$A:$R,G$1-1993,FALSE) -> 0.013812756 | H10: =(VLOOKUP($A10,'Emprego - WIOD-14'!$A:$R,H$1-1993,FALSE)-VLOOKUP($A10,'Emprego - WIOD-16'!$A:$R,H$1-1998,FALSE))/VLOOKUP($A10,'Emprego - WIOD-14'!$A:$R,H$1-1993,FALSE) -> 0.019526997 | I10: =(VLOOKUP($A10,'Emprego - WIOD-14'!$A:$R,I$1-1993,FALSE)-VLOOKUP($A10,'Emprego - WIOD-16'!$A:$R,I$1-1998,FALSE))/VLOOKUP($A10,'Emprego - WIOD-14'!$A:$R,I$1-1993,FALSE) -> 0.02501608 | ... M10: =(VLOOKUP($A10,'Emprego - WIOD-14'!$A:$R,M$1-1993,FALSE)-VLOOKUP($A10,'Emprego - WIOD-16'!$A:$R,M$1-1998,FALSE))/VLOOKUP($A10,'Emprego - WIOD-14'!$A:$R,M$1-1993,FALSE) -> 0.020188427
A11: DEU | B11: =(VLOOKUP($A11,'Emprego - WIOD-14'!$A:$R,B$1-1993,FALSE)-VLOOKUP($A11,'Emprego - WIOD-16'!$A:$R,B$1-1998,FALSE))/VLOOKUP($A11,'Emprego - WIOD-14'!$A:$R,B$1-1993,FALSE) -> -0.019747599 | C11: =(VLOOKUP($A11,'Emprego - WIOD-14'!$A:$R,C$1-1993,FALSE)-VLOOKUP($A11,'Emprego - WIOD-16'!$A:$R,C$1-1998,FALSE))/VLOOKUP($A11,'Emprego - WIOD-14'!$A:$R,C$1-1993,FALSE) -> -0.012539424 | D11: =(VLOOKUP($A11,'Emprego - WIOD-14'!$A:$R,D$1-1993,FALSE)-VLOOKUP($A11,'Emprego - WIOD-16'!$A:$R,D$1-1998,FALSE))/VLOOKUP($A11,'Emprego - WIOD-14'!$A:$R,D$1-1993,FALSE) -> -0.013658686 | E11: =(VLOOKUP($A11,'Emprego - WIOD-14'!$A:$R,E$1-1993,FALSE)-VLOOKUP($A11,'Emprego - WIOD-16'!$A:$R,E$1-1998,FALSE))/VLOOKUP($A11,'Emprego - WIOD-14'!$A:$R,E$1-1993,FALSE) -> -0.012239839 | F11: =(VLOOKUP($A11,'Emprego - WIOD-14'!$A:$R,F$1-1993,FALSE)-VLOOKUP($A11,'Emprego - WIOD-16'!$A:$R,F$1-1998,FALSE))/VLOOKUP($A11,'Emprego - WIOD-14'!$A:$R,F$1-1993,FALSE) -> -0.011754115 | G11: =(VLOOKUP($A11,'Emprego - WIOD-14'!$A:$R,G$1-1993,FALSE)-VLOOKUP($A11,'Emprego - WIOD-16'!$A:$R,G$1-1998,FALSE))/VLOOKUP($A11,'Emprego - WIOD-14'!$A:$R,G$1-1993,FALSE) -> -0.012643234 | H11: =(VLOOKUP($A11,'Emprego - WIOD-14'!$A:$R,H$1-1993,FALSE)-VLOOKUP($A11,'Emprego - WIOD-16'!$A:$R,H$1-1998,FALSE))/VLOOKUP($A11,'Emprego - WIOD-14'!$A:$R,H$1-1993,FALSE) -> -0.014331414 | I11: =(VLOOKUP($A11,'Emprego - WIOD-14'!$A:$R,I$1-1993,FALSE)-VLOOKUP($A11,'Emprego - WIOD-16'!$A:$R,I$1-1998,FALSE))/VLOOKUP($A11,'Emprego - WIOD-14'!$A:$R,I$1-1993,FALSE) -> -0.015129393 | ... M11: =(VLOOKUP($A11,'Emprego - WIOD-14'!$A:$R,M$1-1993,FALSE)-VLOOKUP($A11,'Emprego - WIOD-16'!$A:$R,M$1-1998,FALSE))/VLOOKUP($A11,'Emprego - WIOD-14'!$A:$R,M$1-1993,FALSE) -> 0.0097563275
A12: DNK | B12: =(VLOOKUP($A12,'Emprego - WIOD-14'!$A:$R,B$1-1993,FALSE)-VLOOKUP($A12,'Emprego - WIOD-16'!$A:$R,B$1-1998,FALSE))/VLOOKUP($A12,'Emprego - WIOD-14'!$A:$R,B$1-1993,FALSE) -> -0.0086650819 | C12: =(VLOOKUP($A12,'Emprego - WIOD-14'!$A:$R,C$1-1993,FALSE)-VLOOKUP($A12,'Emprego - WIOD-16'!$A:$R,C$1-1998,FALSE))/VLOOKUP($A12,'Emprego - WIOD-14'!$A:$R,C$1-1993,FALSE) -> -0.0042024084 | D12: =(VLOOKUP($A12,'Emprego - WIOD-14'!$A:$R,D$1-1993,FALSE)-VLOOKUP($A12,'Emprego - WIOD-16'!$A:$R,D$1-1998,FALSE))/VLOOKUP($A12,'Emprego - WIOD-14'!$A:$R,D$1-1993,FALSE) -> -0.0029279378 | E12: =(VLOOKUP($A12,'Emprego - WIOD-14'!$A:$R,E$1-1993,FALSE)-VLOOKUP($A12,'Emprego - WIOD-16'!$A:$R,E$1-1998,FALSE))/VLOOKUP($A12,'Emprego - WIOD-14'!$A:$R,E$1-1993,FALSE) -> -0.00790886 | F12: =(VLOOKUP($A12,'Emprego - WIOD-14'!$A:$R,F$1-1993,FALSE)-VLOOKUP($A12,'Emprego - WIOD-16'!$A:$R,F$1-1998,FALSE))/VLOOKUP($A12,'Emprego - WIOD-14'!$A:$R,F$1-1993,FALSE) -> -0.005322426 | G12: =(VLOOKUP($A12,'Emprego - WIOD-14'!$A:$R,G$1-1993,FALSE)-VLOOKUP($A12,'Emprego - WIOD-16'!$A:$R,G$1-1998,FALSE))/VLOOKUP($A12,'Emprego - WIOD-14'!$A:$R,G$1-1993,FALSE) -> -0.010667011 | H12: =(VLOOKUP($A12,'Emprego - WIOD-14'!$A:$R,H$1-1993,FALSE)-VLOOKUP($A12,'Emprego - WIOD-16'!$A:$R,H$1-1998,FALSE))/VLOOKUP($A12,'Emprego - WIOD-14'!$A:$R,H$1-1993,FALSE) -> -0.011692667 | I12: =(VLOOKUP($A12,'Emprego - WIOD-14'!$A:$R,I$1-1993,FALSE)-VLOOKUP($A12,'Emprego - WIOD-16'!$A:$R,I$1-1998,FALSE))/VLOOKUP($A12,'Emprego - WIOD-14'!$A:$R,I$1-1993,FALSE) -> -0.0056631032 | ... M12: =(VLOOKUP($A12,'Emprego - WIOD-14'!$A:$R,M$1-1993,FALSE)-VLOOKUP($A12,'Emprego - WIOD-16'!$A:$R,M$1-1998,FALSE))/VLOOKUP($A12,'Emprego - WIOD-14'!$A:$R,M$1-1993,FALSE) -> -0.006643928
A13: ESP | B13: =(VLOOKUP($A13,'Emprego - WIOD-14'!$A:$R,B$1-1993,FALSE)-VLOOKUP($A13,'Emprego - WIOD-16'!$A:$R,B$1-1998,FALSE))/VLOOKUP($A13,'Emprego - WIOD-14'!$A:$R,B$1-1993,FALSE) -> -0.017030741 | C13: =(VLOOKUP($A13,'Emprego - WIOD-14'!$A:$R,C$1-1993,FALSE)-VLOOKUP($A13,'Emprego - WIOD-16'!$A:$R,C$1-1998,FALSE))/VLOOKUP($A13,'Emprego - WIOD-14'!$A:$R,C$1-1993,FALSE) -> -0.018735308 | D13: =(VLOOKUP($A13,'Emprego - WIOD-14'!$A:$R,D$1-1993,FALSE)-VLOOKUP($A13,'Emprego - WIOD-16'!$A:$R,D$1-1998,FALSE))/VLOOKUP($A13,'Emprego - WIOD-14'!$A:$R,D$1-1993,FALSE) -> -0.020493032 | E13: =(VLOOKUP($A13,'Emprego - WIOD-14'!$A:$R,E$1-1993,FALSE)-VLOOKUP($A13,'Emprego - WIOD-16'!$A:$R,E$1-1998,FALSE))/VLOOKUP($A13,'Emprego - WIOD-14'!$A:$R,E$1-1993,FALSE) -> -0.022609299 | F13: =(VLOOKUP($A13,'Emprego - WIOD-14'!$A:$R,F$1-1993,FALSE)-VLOOKUP($A13,'Emprego - WIOD-16'!$A:$R,F$1-1998,FALSE))/VLOOKUP($A13,'Emprego - WIOD-14'!$A:$R,F$1-1993,FALSE) -> -0.024867908 | G13: =(VLOOKUP($A13,'Emprego - WIOD-14'!$A:$R,G$1-1993,FALSE)-VLOOKUP($A13,'Emprego - WIOD-16'!$A:$R,G$1-1998,FALSE))/VLOOKUP($A13,'Emprego - WIOD-14'!$A:$R,G$1-1993,FALSE) -> -0.026817458 | H13: =(VLOOKUP($A13,'Emprego - WIOD-14'!$A:$R,H$1-1993,FALSE)-VLOOKUP($A13,'Emprego - WIOD-16'!$A:$R,H$1-1998,FALSE))/VLOOKUP($A13,'Emprego - WIOD-14'!$A:$R,H$1-1993,FALSE) -> -0.029327739 | I13: =(VLOOKUP($A13,'Emprego - WIOD-14'!$A:$R,I$1-1993,FALSE)-VLOOKUP($A13,'Emprego - WIOD-16'!$A:$R,I$1-1998,FALSE))/VLOOKUP($A13,'Emprego - WIOD-14'!$A:$R,I$1-1993,FALSE) -> -0.031820055 | ... M13: =(VLOOKUP($A13,'Emprego - WIOD-14'!$A:$R,M$1-1993,FALSE)-VLOOKUP($A13,'Emprego - WIOD-16'!$A:$R,M$1-1998,FALSE))/VLOOKUP($A13,'Emprego - WIOD-14'!$A:$R,M$1-1993,FALSE) -> -0.047422153
... A41: USA | B41: =(VLOOKUP($A41,'Emprego - WIOD-14'!$A:$R,B$1-1993,FALSE)-VLOOKUP($A41,'Emprego - WIOD-16'!$A:$R,B$1-1998,FALSE))/VLOOKUP($A41,'Emprego - WIOD-14'!$A:$R,B$1-1993,FALSE) -> -0.018391106 | C41: =(VLOOKUP($A41,'Emprego - WIOD-14'!$A:$R,C$1-1993,FALSE)-VLOOKUP($A41,'Emprego - WIOD-16'!$A:$R,C$1-1998,FALSE))/VLOOKUP($A41,'Emprego - WIOD-14'!$A:$R,C$1-1993,FALSE) -> -0.024393023 | D41: =(VLOOKUP($A41,'Emprego - WIOD-14'!$A:$R,D$1-1993,FALSE)-VLOOKUP($A41,'Emprego - WIOD-16'!$A:$R,D$1-1998,FALSE))/VLOOKUP($A41,'Emprego - WIOD-14'!$A:$R,D$1-1993,FALSE) -> -0.026087594 | E41: =(VLOOKUP($A41,'Emprego - WIOD-14'!$A:$R,E$1-1993,FALSE)-VLOOKUP($A41,'Emprego - WIOD-16'!$A:$R,E$1-1998,FALSE))/VLOOKUP($A41,'Emprego - WIOD-14'!$A:$R,E$1-1993,FALSE) -> -0.023419337 | F41: =(VLOOKUP($A41,'Emprego - WIOD-14'!$A:$R,F$1-1993,FALSE)-VLOOKUP($A41,'Emprego - WIOD-16'!$A:$R,F$1-1998,FALSE))/VLOOKUP($A41,'Emprego - WIOD-14'!$A:$R,F$1-1993,FALSE) -> -0.02167429 | G41: =(VLOOKUP($A41,'Emprego - WIOD-14'!$A:$R,G$1-1993,FALSE)-VLOOKUP($A41,'Emprego - WIOD-16'!$A:$R,G$1-1998,FALSE))/VLOOKUP($A41,'Emprego - WIOD-14'!$A:$R,G$1-1993,FALSE) -> -0.020793971 | H41: =(VLOOKUP($A41,'Emprego - WIOD-14'!$A:$R,H$1-1993,FALSE)-VLOOKUP($A41,'Emprego - WIOD-16'!$A:$R,H$1-1998,FALSE))/VLOOKUP($A41,'Emprego - WIOD-14'!$A:$R,H$1-1993,FALSE) -> -0.024380586 | I41: =(VLOOKUP($A41,'Emprego - WIOD-14'!$A:$R,I$1-1993,FALSE)-VLOOKUP($A41,'Emprego - WIOD-16'!$A:$R,I$1-1998,FALSE))/VLOOKUP($A41,'Emprego - WIOD-14'!$A:$R,I$1-1993,FALSE) -> -0.019672351 | ... M41: =(VLOOKUP($A41,'Emprego - WIOD-14'!$A:$R,M$1-1993,FALSE)-VLOOKUP($A41,'Emprego - WIOD-16'!$A:$R,M$1-1998,FALSE))/VLOOKUP($A41,'Emprego - WIOD-14'!$A:$R,M$1-1993,FALSE) -> -0.016146892

Sheet Cálculo
B3: 1995 | C3: 1996 | D3: 1997 | E3: 1998 | F3: 1999 | G3: 2000 | H3: 2001 | I3: 2002 | J3: 2003 | K3: 2004 | L3: 2005 | M3: 2006 | N3: 2007 | O3: 2008 | P3: 2009 | Q3: 2010 | R3: 2011 | S3: 2012 | T3: 2013 | U3: 2014
A4: SOMA-14 | B4: 2.3819196e+09 | C4: 2.4015151e+09 | D4: 2.4242519e+09 | E4: 2.4433032e+09 | F4: 2.4691878e+09 | G4: 2.4910242e+09 | H4: 2.4974756e+09 | I4: 2.5012892e+09 | J4: 2.5073888e+09 | K4: 2.525431e+09 | L4: 2.543913e+09 | M4: 2.5583078e+09 | N4: 2.5763882e+09 | O4: 2.5841708e+09 | P4: 2.5682742e+09 | Q4: 2.572828e+09 | R4: 2.5794083e+09 | S4: 2.5905093e+09 | T4: 2.5982748e+09 | U4: 2.6115955e+09
A5: SOMA-16 | B5: 2.391357e+09 | C5: 2.4110603e+09 | D5: 2.4338326e+09 | E5: 2.4529908e+09 | F5: 2.4788666e+09 | G5: 2.5006507e+09 | H5: 2.5070886e+09 | I5: 2.5109118e+09 | J5: 2.5169767e+09 | K5: 2.5350656e+09 | L5: 2.553577e+09 | M5: 2.5681285e+09 | N5: 2.5864266e+09 | O5: 2.5944483e+09 | P5: 2.5785341e+09 | Q5: 2.5829133e+09 | R5: 2.5895505e+09 | S5: 2.6006813e+09 | T5: 2.6084534e+09 | U5: 2.6219289e+09
A6: ROW-14 | B6: 1.1306054e+09 | C6: 1.1513516e+09 | D6: 1.1740835e+09 | E6: 1.1925191e+09 | F6: 1.2113e+09 | G6: 1.2355738e+09 | H6: 1.257417e+09 | I6: 1.2771579e+09 | J6: 1.3034558e+09 | K6: 1.3335316e+09 | L6: 1.3603665e+09 | M6: 1.3902731e+09 | N6: 1.4209225e+09 | O6: 1.4475743e+09 | P6: 1.4675363e+09 | Q6: 1.4934878e+09 | R6: 1.523623e+09 | S6: 1.5486577e+09 | T6: 1.573223e+09 | U6: 1.5990144e+09
A7: ROW-16 | B7: 1.121168e+09 | C7: 1.1418063e+09 | D7: 1.1645028e+09 | E7: 1.1828314e+09 | F7: 1.2016211e+09 | G7: 1.2259473e+09 | H7: 1.247804e+09 | I7: 1.2675354e+09 | J7: 1.293868e+09 | K7: 1.3238969e+09 | L7: 1.3507025e+09 | M7: 1.3804523e+09 | N7: 1.4108841e+09 | O7: 1.4372969e+09 | P7: 1.4572764e+09 | Q7: 1.4834025e+09 | R7: 1.5134808e+09 | S7: 1.5384857e+09 | T7: 1.5630445e+09 | U7: 1.588681e+09
A10: WIOD-14 | B10: 1.8042469e+09 | C10: 1.8294535e+09 | D10: 1.8512181e+09 | E10: 1.8677215e+09 | F10: 1.8878127e+09 | G10: 1.9259849e+09 | H10: 1.9539633e+09 | I10: 1.9557498e+09 | J10: 1.9918637e+09 | K10: 2.0198075e+09 | L10: 2.0482272e+09 | M10: 2.0693389e+09 | N10: 2.0786529e+09 | O10: 2.0964029e+09 | P10: 2.0876932e+09 | Q10: 2.1293779e+09 | R10: 2.1578842e+09
A11: WIOD-16 | G11: 1.9329204e+09 | H11: 1.9578879e+09 | I11: 1.9823835e+09 | J11: 2.0095397e+09 | K11: 2.0429359e+09 | L11: 2.0641803e+09 | M11: 2.0826754e+09 | N11: 2.1029402e+09 | O11: 2.1164226e+09 | P11: 2.1122808e+09 | Q11: 2.120914e+09 | R11: 2.1917908e+09 | S11: 2.2928696e+09 | T11: 2.3846508e+09 | U11: 2.4622818e+09
A13: Dif-14 | B13: =B10/B4 -> 0.75747599 | C13: =C10/C4 -> 0.76179138 | D13: =D10/D4 -> 0.76362448 | E13: =E10/E4 -> 0.76442479 | F13: =F10/F4 -> 0.76454804 | G13: =G10/G4 -> 0.7731699 | H13: =H10/H4 -> 0.78237535 | I13: =I10/I4 -> 0.78189671 | ... R13: =R10/R4 -> 0.83658108
A14: Dif-16 | G14: =G11/G5 -> 0.77296697 | H14: =H11/H5 -> 0.78094085 | I14: =I11/I5 -> 0.78950744 | J14: =J11/J5 -> 0.79839424 | K14: =K11/K5 -> 0.80587101 | L14: =L11/L5 -> 0.80834859 | M14: =M11/M5 -> 0.81097007 | N14: =N11/N5 -> 0.81306781 | ... U14: =U11/U5 -> 0.93911084
A16: ROW-14 | B16: =B6*B13 -> 8.5640642e+08 | C16: =C6*C13 -> 8.770897e+08 | D16: =D6*D13 -> 8.9655893e+08 | E16: =E6*E13 -> 9.1159114e+08 | F16: =F6*F13 -> 9.2609704e+08 | G16: =G6*G13 -> 9.5530849e+08 | H16: =H6*H13 -> 9.8377206e+08 | I16: =I6*I13 -> 9.9860559e+08 | ... R16: =R6*R13 -> 1.2746342e+09
A17: ROW-16 | G17: =G7*G14 -> 9.4761674e+08 | H17: =H7*H14 -> 9.7446108e+08 | I17: =I7*I14 -> 1.0007286e+09 | J17: =J7*J14 -> 1.0330168e+09 | K17: =K7*K14 -> 1.0668902e+09 | L17: =L7*L14 -> 1.0918384e+09 | M17: =M7*M14 -> 1.1195055e+09 | N17: =N7*N14 -> 1.1471445e+09 | ... U17: =U7*U14 -> 1.4919476e+09

Sheet DATA
A1: VERSAO | B1: 1995 | C1: 1996 | D1: 1997 | E1: 1998 | F1: 1999 | G1: 2000 | H1: 2001 | I1: 2002 | J1: 2003 | K1: 2004 | L1: 2005 | M1: 2006 | N1: 2007 | O1: 2008 | P1: 2009 | Q1: 2010 | R1: 2011 | S1: 2012 | T1: 2013 | U1: 2014
A2: July14 | B2: 8.5640642e+08 | C2: 8.770897e+08 | D2: 8.9655893e+08 | E2: 9.1159114e+08 | F2: 9.2609704e+08 | G2: 9.5530849e+08 | H2: 9.8377206e+08 | I2: 9.9860559e+08 | J2: 1.0354622e+09 | K2: 1.0665416e+09 | L2: 1.0952968e+09 | M2: 1.1245504e+09 | N2: 1.1464129e+09 | O2: 1.1743415e+09 | P2: 1.1929278e+09 | Q2: 1.2360717e+09 | R2: 1.2746342e+09
A3: Nov16 | G3: 9.4761674e+08 | H3: 9.7446108e+08 | I3: 1.0007286e+09 | J3: 1.0330168e+09 | K3: 1.0668902e+09 | L3: 1.0918384e+09 | M3: 1.1195055e+09 | N3: 1.1471445e+09 | O3: 1.1724757e+09 | P3: 1.1937701e+09 | Q3: 1.21807e+09 | R3: 1.2810073e+09 | S3: 1.3563935e+09 | T3: 1.4289368e+09 | U3: 1.4919476e+09
A4: was_w | B4: 43.268769 | C4: 43.269146 | D4: 43.520865 | E4: 43.406635 | F4: 43.206123 | G4: 43.25349 | H4: 43.345524 | I4: 43.445337 | J4: 43.532751 | K4: 43.859931 | L4: 44.103252 | M4: 44.51054 | N4: 44.898271 | O4: 45.212982 | P4: 45.32024 | Q4: 45.498332 | R4: 45.589613 | S4: 45.956251 | T4: 46.304752 | U4: 46.606741

Sheet Assalariados - WorldBank
B1: 1995 | C1: 1996 | D1: 1997 | E1: 1998 | F1: 1999 | G1: 2000 | H1: 2001 | I1: 2002 | J1: 2003 | K1: 2004 | L1: 2005 | M1: 2006 | N1: 2007 | O1: 2008 | P1: 2009 | Q1: 2010 | R1: 2011 | S1: 2012 | T1: 2013 | U1: 2014
